Workbook

Sheet Info
B2: Hello 👋
B4: Welcome to the labeling exercise for SDG 17.
B5: The objective of this exercise is to label 100 texts in terms of their relevance to SDG 17.
B7: Your Labeling Sheet
B8: You have your own personal sheet for assigning the labels. You will find it by clicking on your name in the list at the bottom of this page.
B9: Each sheet has the same 100 texts, but the order in which they appear has been randomized.
B10: Later on, we will put everyone's labels side-by-side. This will help us identify texts with high and low alignment.
B11: At our next meeting, we will discuss the texts where we have disagreements and see if we can reach a consensus for the "true" label for every text.
B12: Please resist the temptation to look at other people's labels until you are done labeling. 🙂
B14: Explanation of Labels
B15: On your personal sheet, you will find the text in column B.
B16: Column C contains a drop-down for picking the appropriate label. The options are:
B18: TRUE | C18: This text is relevant to SDG 17
B19: FALSE | C19: This text is not relevant to SDG 17
B20: SKIP | C20: You can use this if you are not sure about the label
B22: If you want, you can put any comments in column D.
B24: Instructions for Labeling
B25: The text should be annotated as SDG 17 only if:
B27: 1. The text addresses SDG 17 or one of its targets
B28: See the official definitions of SDG 17 and its targets below ("SDG 17 Description & Targets").
B30: AND
B32: 2. The text addresses SDG 17 or its targets directly:
B33: - the text should be directly relevant to SDG 17 or to achieving SDG 17
B34: - if a text only has an indirect or implicit relevance, it should not be labeled SDG 17
B36: AND
B38: 3. The text addresses SDG 17 or its targets specifically:
B39: - the text should be specific to SDG 17 and its targets
... B48: SDG 17 Description & Targets
B49: SDG 17 | C49: Strengthen the means of implementation and revitalize the global partnership for sustainable development
B50: Target 17.1 | C50: Strengthen domestic resource mobilization, including through international support to developing countries, to improve domestic capacity for tax and other revenue collection
B51: Target 17.2 | C51: Developed countries to implement fully their official development assistance commitments, including the commitment by many developed countries to achieve the target of 0.7 per cent of ODA/GNI to developing countries and 0.15 to 0.20 per cent of ODA/GNI to least developed countries; ODA providers are encouraged to consider setting a target to provide at least 0.20 per cent of ODA/GNI to least developed countries
B52: Target 17.3 | C52: Mobilize additional financial resources for developing countries from multiple sources
B53: Target 17.4 | C53: Assist developing countries in attaining long-term debt sustainability through coordinated policies aimed at fostering debt financing, debt relief and debt restructuring, as appropriate, and address the external debt of highly indebted poor countries to reduce debt distress
B54: Target 17.5 | C54: Adopt and implement investment promotion regimes for least developed countries
B55: Target 17.6 | C55: Enhance North-South, South-South and triangular regional and international cooperation on and access to science, technology and innovation and enhance knowledge sharing on mutually agreed terms, including through improved coordination among existing mechanisms, in particular at the United Nations level, and through a global technology facilitation mechanism
B56: Target 17.7 | C56: Promote the development, transfer, dissemination and diffusion of environmentally sound technologies to developing countries on favourable terms, including on concessional and preferential terms, as mutually agreed
B57: Target 17.8 | C57: Fully operationalize the technology bank and science, technology and innovation capacity-building mechanism for least developed countries by 2017 and enhance the use of enabling technology, in particular information and communications technology
B58: Target 17.9 | C58: Enhance international support for implementing effective and targeted capacity-building in developing countries to support national plans to implement all the sustainable development goals, including through North-South, South-South and triangular cooperation
B59: Target 17.10 | C59: Promote a universal, rules-based, open, non-discriminatory and equitable multilateral trading system under the World Trade Organization, including through the conclusion of negotiations under its Doha Development Agenda
B60: Target 17.11 | C60: Significantly increase the exports of developing countries, in particular with a view to doubling the least developed countries’ share of global exports by 2020
...

Sheet Finn
A1: Text ID | B1: Text | C1: SDG 17 Label | D1: Comments (optional)
A2: daed8f635ad6c363df5ffa2916ea6bdb | B2: This source of funding is actually a number of different sources, with funds flowing from various donors through the World Bank and other agents, to countries that take action to reduce emissions from their forestry sectors. The Fund currently has US$10 billion in committed funding available. In an innovative arrangement, financing is available not only to states (and public bodies such as environment or development ministries, development banks), but also to the private sector.13 Also worth noting is the intention to roughly balance investment between mitigation and adaptation, with at least half of the latter funds going to those countries most vulnerable to the impacts of climate change: least developed countries (LDCs), small island states and African states. | C2: TRUE
A3: 6ce24f152679d754070b98a6e68b0816 | B3: Three other targets refer to the potential of ICTs for achieving other Goals, and indicators adopted by UNSC for these four targets are discussed in this chapter. Several other Goals and targets refer more generally to the importance of technology and to the role of information in enabling the achievement of sustainable development. It will provide the basis for annual monitoring, follow-up and subsequent review of implementation of the 2030 Agenda at the national, regional and global levels. | C3: TRUE
A4: 3a629c9297c945d4187f08ee281c6475 | B4: In either case, further monitoring and research are needed to understand the underlying causes. Indicators offer a measure of the effectiveness of actions in moving a system towards a more desirable state. For example, if body temperature decreases after taking a medicine, we conclude that the medicine has been effective in combating the disease. To accomplish this objective, indicators should provide an ability to assess cause-and-effect relations. They help policy makers and the public to understand the linkages and trade-offs between economic, environmental and social values in order to evaluate the long-term implications of current decisions and behaviour and to monitor progress towards sustainable development goals by establishing baseline conditions and trends. | C4: TRUE
A5: a5b0f691bf38ae1ba9b11ce474551016 | B5: Delivering on SDG 14 requires teamwork and a spirit of partnership among diverse stakeholders from many nations and sectors. The oceans cover almost three quarters of the Earth’s surface, storing one third of all the carbon emissions stemming from human activity. They are part of the solution, and we must make them a key focus of our efforts to cope with and mitigate climate change. | C5: TRUE
A6: 4efe676a22c7c8b91cc45d3403290313 | B6: Nevertheless, as in many other countries, an institutional culture of multiple silo-type ministries still prevails. Ensuring high-profile leadership or co-ordination would help improve policy coherence and enable a whole-of-government approach to sustainable development. For instance, about a quarter of municipal environmental councils were inactive in 2013 (IBGE, 2014). Many state agencies face a significant challenge to attract and retain qualified technical staff. | C6: TRUE
A7: 03e4a6dde7176e5c9f4fd24941db7652 | B7: Journal of Marriage and the Family, 131-146. Gender & Development, 23(2), 279-297. Intimate partner violence: causes and prevention. The Lancet', 359:1423-29. Relationship between alcohol-attributable disease and socioeconomic status, and the role of alcohol consumption in this relationship: a systematic review and meta-analysis. Psychology of Violence (in press). | C7: FALSE
A8: 99e9feacfccae32759999fc34e54dfde | B8: Many proposals for increasing financial resources have been made (Stiglitz, 2006, UNEP, 2011, UNDESA, 2011). Many of the incentive-related instruments may help raising financial resources, but other, additional, mechanisms have to be identified. National authorities could collect taxes on the basis of national legislation, to feed either national or international funds. Taxes could also be levied internationally, on the basis of agreements. | C8: TRUE
A9: fb8ebc8b40293435f1f98c4b0c21c2a8 | B9: Yet, little comprehensive evidence is collected on how many women-owned and managed companies participate in international trade, what type of products they export or what barriers discourage women from entering international trade. Because of these issues, it is difficult to draw a comprehensive picture of women’s participation in international trade. The findings contribute to a better understanding ot women’s limited participation in international trade. For the sake ot simplicity, the analysis concentrates on exporting firms, including firms that both export and import. Surveyed firms that only import were not considered in this analysis. | C9: FALSE
A10: a1f114a34a446f7afbfc933748a634a8 | B10: Accessing international capital markets can also be difficult for many developing countries. These challenges can be further exacerbated for clean energy infrastructure projects, as lenders may be reluctant to lend due to an insufficient knowledge of local markets and a higher technology risk. Ensuring access to affordable finance will require developing country governments, in particular, to combine a short-term strategy of facilitating access to international financing and a longer-term approach. The latter would need to address the full range of risks and limitations that increase the cost of financing for clean energy, including: the shallowness of the domestic financial market, key informational, social or behavioural risks related to clean energy financing, and the limited number of financial products that are available and suited to the sector’s financing needs. In some countries, like Brazil or China, bank lending has played a predominant role, with state-owned and/or national development banks being the main sources of long-term financing. In China for example, banks hold around 80% of the total loan portfolio for infrastructure (Walsh et al., | C10: TRUE
A11: 40c1e663bf9eafcd5f47c74f01059e99 | B11: The WTO's specific contributions to the SDGs also include: ensuring access to affordable medicines in developing countries (SDG 3.b): implementing the principle of special and differential treatment to help reduce inequalities (SDG 1Q.a): and ongoing discussions on eliminating subsidies that cause overfishing and overcapacity (in order to help achieve SDG 14.6). In addition, the WTO's work on the reduction of tariff and non-tariff barriers on environmental goods and services can facilitate the diffusion of green technologies and therefore directly contribute to environmental sustainability. In this way, the WTO can ensure that the multilateral trading system contributes to building a more favourable global environment for inclusive growth and development. Over the past twenty years, international trade has undergone major changes due to a variety of economic, political and technological factors. Undoubtedly, one main leading factor of change has been the unprecedented pace of technological innovation, which has transformed traditional ways of conducting trade. Advances in ICTs have led to reduced costs and increased speed and efficiency of economic transactions, with significant productivity gains for the global economy. | C11: TRUE
A12: b229680228472a4134aba057b2269b1e | B12: The goal of the programme is to support the development of new innovations with smart, innovation-friendly public procurements. The programme encourages public buyers to use procurement to solve societal problems, renew public services, and improve market access for new products and services. Over the period 2009-16, funding covered a total of EUR 11 million for 73 ended projects. The main areas that received funding are environment/building (36%) and social and health (26%). | C12: FALSE
A13: 004d7719d6c26c11427bb3e89535efab | B13: Foster capacity-building at all levels of government. This implies combining investment in physical water and sanitation “hard” infrastructure with the provision of “soft’ infrastructure, which is essentially the institutions upon which water outcomes rely. The development of skills, technical expertise and knowledge and the availability of staff and time are preconditions for effective governance of water policy. | C13: FALSE
... A101: 43d82531e93637ae336b46c58cfcb026 | B101: It can also support capacity development and provide technical assistance to strengthen local institutions and contribute to domestic resource mobilisation and the engagement of the private sector. The emphasis on different goals will be based on national circumstances. Nevertheless, the SDGs do increase the overall scope of issue development co-operation will play a role in. | C101: TRUE

Sheet Gib
A1: Text ID | B1: Text | C1: SDG 17 Label | D1: Comments (optional)
A2: d02e6530cd8f1e22d6c333c1d3602a03 | B2: The competent state agency controls products in Group 2 on the basis of relevant technical regulations as well as by producers on the basis of applicable standards. Different ministries are responsible for the control of quality of products and goods under their responsibility, and for issuing lists of products and goods that can cause "unsafety" and are subject to mandatory inspection. These were removed for tea and coffee in 1995. However, coffee beans remained subject to line management by MARD requiring their approval before export. Export quotas on rice were introduced in 1992 to ensure food security and price stability. | C2: FALSE
A3: 00d1f63db99df50cb6e61519d2a32f50 | B3: This technology bank for the LDCs was officially established on 23 December 2016, through the adoption of the UN General Assembly Resolution A/71/L.52. In addition, ITU's Membership recognized the importance of ICTs for LDCs by adopting specific targets for the LDCs in its Connect 2020 Agenda (ITU, 2014). Target 2, on inclusiveness, includes specific targets on household access to ICTs, Internet use, and affordability in the LDCs. Most have been primarily based on basic, low-bandwidth mobile cellular technologies. | C3: TRUE
A4: 22a8c8ad7fca121559996cf5be31d969 | B4: The international community has created processes for monitoring progress at the regional and global levels, and for countries to exchange policy experiences, to learn from each other, and to coordiante their policies where appropriate. The present chapter contributes to this effort by analyzing how the current innovation policies of Kyrgyzstan contribute to the country’s national sustainable development priorities, comparing current policies to international good practice, and recommending policy reforms that could further encourage innovations contributing to sustainable development. The present chapter focuses on the other two pillars of sustainable development, i.e. environmental sustainability and social inclusiveness. However, it should be noted that failures to address unsustainable practices has a very real economic cost. While no estimates of this cost are available for Kyrgyzstan at present, the World Bank has for instance estimated that for neighboring Tajikistan the direct and indirect economic damage caused by environmental degradation may be as high as 8 percent of GDP.90 Thus the key to sustainable development is to achieve all three dimensions together, rather than achieving one at the expense of the others. | C4: TRUE
A5: daed8f635ad6c363df5ffa2916ea6bdb | B5: This source of funding is actually a number of different sources, with funds flowing from various donors through the World Bank and other agents, to countries that take action to reduce emissions from their forestry sectors. The Fund currently has US$10 billion in committed funding available. In an innovative arrangement, financing is available not only to states (and public bodies such as environment or development ministries, development banks), but also to the private sector.13 Also worth noting is the intention to roughly balance investment between mitigation and adaptation, with at least half of the latter funds going to those countries most vulnerable to the impacts of climate change: least developed countries (LDCs), small island states and African states. | C5: TRUE | D5: 17.3
A6: 004d7719d6c26c11427bb3e89535efab | B6: Foster capacity-building at all levels of government. This implies combining investment in physical water and sanitation “hard” infrastructure with the provision of “soft’ infrastructure, which is essentially the institutions upon which water outcomes rely. The development of skills, technical expertise and knowledge and the availability of staff and time are preconditions for effective governance of water policy. | C6: TRUE
A7: 26443f27488420a4af1a208fd73f5bbd | B7: In 2015, the geographic scope was expanded to include small island developing States in the Pacific. It contributes to the narrowing of capacity gaps through regional and South-South cooperation, sharing of resources and the development of an integrated regional warning system comprising a network of collaborative centres. Civil society innovations and business sector initiatives. | C7: TRUE
A8: 02bac9d17475999b1e8cd569255dca67 | B8: Strategies include building national and regional institutional capacity, cost sharing across borders, governance and regulations, enhancing access to modern energy, developing low-carbon and renewable domestic resources, improving regional energy cooperation and energy security, and promoting private sector participation in energy development. One key focus area is the development of hydropower potential, especially in the Lao People's Democratic Republic. Other activities pertaining to the energy sector include issues related to development of new and renewable sources (including small hydro), addressing the food-energy nexus, standardization and testing. These are captured in the BIMSTEC Memorandum of Understanding on Grid Interconnection. | C8: TRUE
A9: 04c57f6f2e4df1bb8aecd8022b77a04d | B9: When asked “Have you no morals?” Alfred Doolittle in George Bernard Shaw’s Pygmalion answered: “Can’t afford them governor. Neither could you if you was as poor as me.” The modern concept of human rights underpins a moral society and holds governments responsible for fulfilling these rights. From informed consent to the right to privacy civil and political rights have dominated the human rights focus of the HIV-1 epidemic. Yet the economic and social rights of people with HIV-1 infection in particular the rights to health care and to share in scientific advances are glaringly disparate between rich and poor countries. This disparity has become the focus of debate in transnational HIV-1 vaccine research. (excerpt) | C9: TRUE
A10: 9cd5d99078edee795d3fdf0d3db91b76 | B10: Programmes for facing the development challenges of the poorest and the hungriest have also been expanded. This includes the heavily indebted poor countries (HIPC) and Enhanced HIPC Initiatives, Education for All Fast Track Initiative (EFA-FTI), and other similar measures. The international assistance programmes have begun to focus on the poorest countries and peoples to complement the BPoA. The World Summit (September 2005) reiterated the commitments of the donors to fulfil the BPoA target of providing 0.15-0.20 per cent of GNI as ODA to the LDCs. | C10: TRUE
A11: 1daecd588ace044156e92e055f44126e | B11: Moreover, the indicators should be developed which support the monitoring of the Global Goals for Sustainable Development (SDGs) adopted in 2015 by the UN General Assembly. This will ensure more accurate assessment of sustainable development progress and, if necessary, lead to adjustment of urban development policy. For example, a private construction practice of building several houses on six-acre (rural areas) and four-acre (urban areas) plots exists. It is essential to monitor this process and update development density and infrastructure indicators. | C11: TRUE | D11: 17.19
A12: 605d237deafbadf27e954abd4754320e | B12: However, rail transport has an important role to play in the growth and sustainable development of the African continent over the next few decades (AfDB, 2015). For instance, more than 95% of Ethiopia's trade passes through the port of Djibouti. The new Addis Ababa-Djibouti railway provides landlocked Ethiopia with railroad access to the sea. The new line was built between 2011 and 2016 and financed by China at around USD 4 billion. | C12: FALSE
A13: 6115053d50939c957db047657c98311c | B13: They may also capture the experiences of adult survey respondents, providing guidance on the nature and prevalence of those respondents' food needs. In terms of measurement, existing systems do not tap children's perspectives on their own lives, nor do they flow from a conceptualization of food insecurity that is grounded in children's experiences, their roles within households, or the ways in which they make sense of their environments. Adult survey respondents tend to under-report child food insecurity, missing as many as half of children who, themselves report going hungry because there is not enough food [16]. In terms of delivery, these systems rely on household samples, which exclude children in institutional settings and homeless children, and can substantially under-represent them in highly vulnerable household situations (migrant workers, those living in urban slums, distant rural households, those living in refugee camps, multi-family or extended family households) [17]. | C13: TO DO
A14: 73f015cb5eeb37a0cda89d82ec481729 | B14: It provides an overview of the financing for development agenda, highlighting the critical role of official development assistance (ODA) for the least developed countries, as well as its catalytic role in higher-income developing countries. The chapter analyses2002-15aggregate aid-for-trade disbursements (around USD 300 billion) and takes a detailed look at aid-for-trade programmes that are building physical and digital connectivity. It offers a brief overview of academic findings on the results of aid-for-trade investments, as well as recent evaluations of donor aid-for-trade strategies and programmes. Case stories show how aid for trade is helping countries improve their physical and digital connectivity, turning trade opportunities into trade flows. Finally, the chapter provides an analysis of aid-for-trade commitments in 2015, closing with a series of conclusion. | C14: TO DO
A15: 587d2c3437cf5dd56dcf301b5246d2ee | B15: This being said, information on foreign applications and grants could also help a developing country patent examiner to better identify those particular elements of an invention that do not deserve patent protection. Where the line is drawn between those areas that are the preserve of the patent holder to control, and those areas [i.e. of exceptions and limitations] which the patent holder may not control, is therefore a very important policy question for members.” Exceptions to exclusive rights as considered here apply after a patent has been granted. | C15: TO DO
A16: 8d663f2f8836003e9e59158d4b98d2ab | B16: In order to encourage corporatisation, the government agreed to assume part of the debts of those hospitals willing to go through that process until the end of 2013. The Ministry of Health gave hospital authorities an opportunity to transform indebted tertiary-care facilities from publicly owned institutions managed by local governments into companies owned by such governments with the further option to also involve a private investor. In the 2009-11 period, this form of transformation of public health-care units was supported by public resources from the general budget. | C16: TO DO
A17: 1a93663faa4b02d59c40f839d323648d | B17: International, regional and subregional organizations can also contribute by coordinating efforts on developing methodologies, collecting data and providing technical assistance to improve migration data, including those required to monitor migrationrelevant Sustainable Development Goal indicators and the implementation of the global compact on migration. As an increasing number of people live in cities, well-managed urbanization can help cities to reap the benefits of agglomeration while minimizing environmental degradation and other adverse impacts of urban growth. Urban planning is critical for the sustainable development of an urban infrastructure for providing access for all, especially the urban poor, to essential services, including safe water and sanitation, health care, education and adequate housing. | C17: TO DO
A18: a33ed0dba09a2ffca4f24943e4fff696 | B18: The following chapter examines policy coherence and the importance of local strategies to job creation. This does not necessarily correspond to the municipal level, where the public employment service has its antennas. Such municipal offices are often merely delivery agencies with low critical mass and strategic capacity, except in urban centres. | C18: TO DO
A19: 7f0f4057da4f1ac3ac1cc53d7c9d0d8b | B19: Governments introduced several measures in order to help families, for instance measures of debt relief. As a result, firms started to cut jobs or reduce wages. Moreover, they increasingly used temporary employment contracts without benefits, and more generally entailing a reduction in job security and deterioration in job quality. | C19: TO DO
A20: 065b94a23d80f4253f10e7f437e2a938 | B20: Some concerns were raised that they were a disruptive force with regard to the WTO-led multilateral trading system, compared with the inclusive and consensual nature ofthe latter regime, these regional negotiations excluded the majority ofthe world's countries and people yet could affect them in various ways. The Trade Facilitation Agreement (TFA), adopted at Bali in 2013, is the biggest multilateral trade deal of the past 20 years (discussed later). The WTO-led Aid for Trade (AfT) initiative shows trade multilateralism can be responsive to the concerns ofthe most capacity-constrained members and can help address their development needs. The TFA's implementation is also directly linked to parties' capacity, with technical assistance available to help in this regard. More importantly, in today's turbulent times, the WTO still provides the best rules-based governance framework for world trade and safeguards the development interests of the world's smallest and poorest countries. Commonwealth members could lead the way by reaffirming their commitment to a free, fair and inclusive multilateral trading system that supports the implementation of the 2030 Agenda for Sustainable Development. | C20: TO DO
A21: b56e57501cd56ce5d7ebf243cc31fd86 | B21: Strong real economy investments, large and small, with their important job-creating capacity must displace financial operations from the driver's seat of the global economy. The expansion of short-term profits in financial markets, with little employment to show for it, has channelled away resources from the longer term horizon of sustainable real economy enterprises. The world is awash in liquidity that needs to become productive investments through a regulatory framework ensuring that financial institutions fulfil their original role of channelling savings into the real economy. Also, expanding wage participation in GDP within reasonable inflation rates will increase real demand and serve as a source of sustainable development growth. | C21: TO DO
A22: f0abe1e91ba984d37c603966e03812a2 | B22: However, the viability of existing global governance in managing value chains has not been given due consideration to date. Given the very real forces of convergence and divergence in operation within the global economy, there are concerns that the ascendency of GVCs might actually accentuate these processes (Keane and Basnett 2015). Almost half of global merchandise exports and about 40 per cent of world GDP are now attributable to developing countries. | C22: TO DO
A23: ae3d99dad941bde5e3b0473fe5645ee0 | B23: Studies have been carried out in the region that show deficiencies in pension and retirement benefit coverage that have a larger impact on women, who receive roughly 20% less than men, on average (Marco, 2016, CEPAL, 2016a). In recent years, time has become the subject of study as a measure of well-being: the problem of poverty has been analysed from various unconventional perspectives and a vicious circle involving poverty and time spent on unpaid work has been revealed (Vaca-Trigo, 2015, CEPAL, 2016a). Hence, in order to achieve sustainable development, it is important to consider this dimension when designing public policies. As shown in figure IV.11, poor women receiving transfers in both countries spend more hours per week on unpaid domestic and care work. | C23: TO DO
A24: 5e5dbac2056edc34caa6e204bbe0d5b4 | B24: The paper reports a study that investigated the construction of a common identity in an online Italian forum of psychologists based on asynchronous CMC. Discourse analysis was carried out on 20 discussions, and three Interpretative Repertoires were identified: (i) Professional Boundaries, (ii) disempowered psychology and (iii) psychology and health, which refer to three recurrent modalities of constructing the psychological profession. The study suggests that a framework drawing on social constructionism and Bourdieu's critical theory can help understand some aspects of identity in, and across, communities of practice. The main conclusion is that analysing critically how identities are constructed in learning environments, virtual or not, allows reconsidering the role of the cultural context in the production of those identities. | C24: TO DO
... A101: 04b753487d64d031f9aee7ce5befed51 | B101: This paper assesses the extent to which solutions under Dutch civil law complement and augment the public policy objectives underlying the criminalization of corruption in international business transactions. To this end, it explores the contractual and non-contractual consequences of contracts tainted by corruption as well as the rules of private international law that come into play with regard to such “corrupt” contracts under Dutch law. | C101: TO DO

Sheet Ivan
A1: Text ID | B1: Text | C1: SDG 17 Label | D1: Comments (optional)
A2: 03e4a6dde7176e5c9f4fd24941db7652 | B2: Journal of Marriage and the Family, 131-146. Gender & Development, 23(2), 279-297. Intimate partner violence: causes and prevention. The Lancet', 359:1423-29. Relationship between alcohol-attributable disease and socioeconomic status, and the role of alcohol consumption in this relationship: a systematic review and meta-analysis. Psychology of Violence (in press). | C2: FALSE
A3: 009408d19e771891fcce817c7c7316db | B3: Following their concerns that physicians across the Japanese health system were not able to identify signs of psychological distress which could help reduce suicide, the Japanese Medical Association reports that they began sharing information and guidance on depression with all doctors, first in 2004 and then again in 2009. At present, only indicators on the rate of seclusion and restraint, and involuntary admission, are collected by providers and at a Prefectural level. Systematically collected information on the mental health care system is limited to structural indicators - facilities, staff numbers, bed numbers. | C3: FALSE
A4: 004d7719d6c26c11427bb3e89535efab | B4: Foster capacity-building at all levels of government. This implies combining investment in physical water and sanitation “hard” infrastructure with the provision of “soft’ infrastructure, which is essentially the institutions upon which water outcomes rely. The development of skills, technical expertise and knowledge and the availability of staff and time are preconditions for effective governance of water policy. | C4: SKIP | D4: If it is about developing country then yes, otherwise no?
A5: 00defece7fdb7a55891994903a193734 | B5: Information and transaction costs include obstacles that firms have to overcome in order to search for trading partners, acquiring information about tastes, regulations and technical requirements, and enforcing contracts. World Bank-ESCAP database on International trade costs. Each time series is standardized to 100 at the beginning of the sample period. | C5: FALSE | D5: Seem to be just a fact so not really related?
A6: 04c57f6f2e4df1bb8aecd8022b77a04d | B6: When asked “Have you no morals?” Alfred Doolittle in George Bernard Shaw’s Pygmalion answered: “Can’t afford them governor. Neither could you if you was as poor as me.” The modern concept of human rights underpins a moral society and holds governments responsible for fulfilling these rights. From informed consent to the right to privacy civil and political rights have dominated the human rights focus of the HIV-1 epidemic. Yet the economic and social rights of people with HIV-1 infection in particular the rights to health care and to share in scientific advances are glaringly disparate between rich and poor countries. This disparity has become the focus of debate in transnational HIV-1 vaccine research. (excerpt) | C6: FALSE
A7: 0342980e48fbffd359a20628d9450485 | B7: Mauritius covers a total land area of 720 square miles, and is almost entirely of volcanic origin, except for stretches of beaches, coral reefs and small patches of alluvium at the mouths of rivers. Pear-shaped, mountainous with its highest peak standing at 2,711 feet above sea level, Mauritius emerged from the ocean floor some 5 million years ago. Volcanic activity over thousands of years has given rise to varied types of soil. | C7: FALSE
A8: edb3e38847428a4f7892de106059e067 | B8: There are several examples of highly fragmented contexts (Canada, France, Mexico) where the multiple actors and layers usually perceived as obstacles to policy coherence have been compensated by the adoption of sound co-ordination mechanisms (see below) that reduced, to a more or less important degree, the impact of sectoral fragmentation. In federal states with important geographical and hydrological disparities (Australia, Canada, the United States), or strong regional characteristics (Belgium), local and regional authorities are the main actors in water-resources management and service delivery. In most cases (EU countries), sub-national governments play a significant role in the design and implementation of water policies, together with the central government, while in some countries (Chile, Israel, Japan, Korea), they are mostly “implementers” of central government policies, with low involvement in the “design” stage. In addition, there are very few significant river basin scale organisations and the institutional mapping and governance challenges vary greatly from one state to another. | C8: SKIP
A9: 01c00b8ad04f55efa35102a1e913d234 | B9: Africa Gender Equality Index 2015, African Development Bank, Abidjan, http://www.afdb.org/fileadmin/uploads/afdb/ Documents/Publications/Afric an_Gender_Equality_lndex_2015-EN.pdf. Gender, Poverty and Environmental Indicators on African Countries, Vol XV, African Development Bank. Regional Road Map, OECD/SWAC, Paris, https://www.oecd. | C9: FALSE
A10: 065b94a23d80f4253f10e7f437e2a938 | B10: Some concerns were raised that they were a disruptive force with regard to the WTO-led multilateral trading system, compared with the inclusive and consensual nature ofthe latter regime, these regional negotiations excluded the majority ofthe world's countries and people yet could affect them in various ways. The Trade Facilitation Agreement (TFA), adopted at Bali in 2013, is the biggest multilateral trade deal of the past 20 years (discussed later). The WTO-led Aid for Trade (AfT) initiative shows trade multilateralism can be responsive to the concerns ofthe most capacity-constrained members and can help address their development needs. The TFA's implementation is also directly linked to parties' capacity, with technical assistance available to help in this regard. More importantly, in today's turbulent times, the WTO still provides the best rules-based governance framework for world trade and safeguards the development interests of the world's smallest and poorest countries. Commonwealth members could lead the way by reaffirming their commitment to a free, fair and inclusive multilateral trading system that supports the implementation of the 2030 Agenda for Sustainable Development. | C10: TRUE
A11: 69b9b9ed677e2a780b473808670fbb03 | B11: While common factors help determine labour market participation for both women and men, women often face a far more restrictive range of such factors compared with men. Household and social norms in the subregion assume that women take the vast majority of responsibility for domestic work and caregiving and are sometimes restricted from labour market participation altogether if household income levels are sufficiently high. Labour market segmentation and economic decision-making norms restrict the range of possible jobs in which women can participate. Low incomes and high informality in segmented occupations and economic activity create significant gender gaps in participation in premium-level formal employment. | C11: FALSE
A12: 22bc84c637e02ea9eb996181bf505b3e | B12: Regular household surveys are not yet undertaken in many countries, especially LDCs, and do not always follow the same guidelines for data gathering on ICTs. The rapid pace of change in technology and markets also affects the comparability of data, so that targets and indicators need to be kept under review and updated from time to time to meet changing data availability and policy requirements. More attention also needs to be addressed to building the capacity of national statistical offices and others concerned with data gathering and analysis. | C12: TRUE
A13: b56e57501cd56ce5d7ebf243cc31fd86 | B13: Strong real economy investments, large and small, with their important job-creating capacity must displace financial operations from the driver's seat of the global economy. The expansion of short-term profits in financial markets, with little employment to show for it, has channelled away resources from the longer term horizon of sustainable real economy enterprises. The world is awash in liquidity that needs to become productive investments through a regulatory framework ensuring that financial institutions fulfil their original role of channelling savings into the real economy. Also, expanding wage participation in GDP within reasonable inflation rates will increase real demand and serve as a source of sustainable development growth. | C13: TRUE
A14: c6c157e0d9e70b30426c105a02ecb05a | B14: This is particularly pressing in developing countries where young people often lack job-ready skills and Al platforms, tools, and applications are scarce. In the least developed countries (LDCs), a lack of mass digitalization and low penetration of broadband mean there is insufficient data for machine learning and deep learning. There is also a lack of transparency in the use of education data to ensure algorithmic accountability, privacy and data transparency. | C14: TRUE
A15: 655e9ad47325067ae4487b9347774527 | B15: Government leaders from more than 150 countries confirmed at the world summit in Johannesburg xo years later that the convention is the key instrument for the conservation and sustainable use of biological diversity and the fair and equitable sharing of benefits arising from use of genetic resources. It emphasises the need for counteracting the loss of biological diversity through conservation and sustainable development. Genetic variations within the species, for example in the populations of the same species spread over a large area, are also covered by the term. | C15: TRUE
A16: ab2c7068988202411d5b93c93571c595 | B16: Accessing international capital markets can also be difficult for many developing countries. These challenges can be further exacerbated for clean energy infrastructure projects, as lenders may be reluctant to lend due to an insufficient knowledge of local markets and a higher technology risk. Ensuring access to affordable finance will require developing country governments, in particular, to combine a short-term strategy of facilitating access to international financing and a longer-term approach. | C16: TRUE
A17: d02e6530cd8f1e22d6c333c1d3602a03 | B17: The competent state agency controls products in Group 2 on the basis of relevant technical regulations as well as by producers on the basis of applicable standards. Different ministries are responsible for the control of quality of products and goods under their responsibility, and for issuing lists of products and goods that can cause "unsafety" and are subject to mandatory inspection. These were removed for tea and coffee in 1995. However, coffee beans remained subject to line management by MARD requiring their approval before export. Export quotas on rice were introduced in 1992 to ensure food security and price stability. | C17: TRUE
A18: 95034907d6a34f440af3bc94d53616c9 | B18: As Minister of Health, she implemented healthcare reform, improving attention to primary care facilities with the aim of ensuring better and faster healthcare response for families. She highlights the contribution that official development assistance (ODA) has made to empowering women and girls to exercise their rights fully as equal citizens. Partnerships on gender equality between the United Nations (UN) and the Organisation for Economic Co-operation and Development (OECD) have also played a fundamental role in ensuring enhanced support to and impact on gender equality goals, particularly as the deadline for achieving the Millennium Development Goals (MDGs) approaches. | C18: TRUE
A19: c143c038ae310e7c5d15d9f7d7cfbce1 | B19: If the capacity of national data centers is limited, storage and cloud computing applications will be located abroad, adding to the need and subsequent costs of international bandwidth as well as increasing dependency on external networks over which there is no control. See: Alaerds et al. This section reviews domain name developments among LDCs. It explores the important benefit that can accrue for LDCs by bundling domain names with local web hosting to build up the national Internet ecosystem, develop skills and generate employment. | C19: TRUE
A20: c0e623b99899a1d8f19efca591f9846a | B20: The Paris Agreement continues this bifurcation in some respects by not making reporting on financial, technology transfer and capacity-building support received mandatory (Article 13.10 indicates that developing countries “should” provide this information). However, the Paris Agreement does indicate that developed countries “shall” biennially communicate indicative quantitative and qualitative information on climate finance, technology transfer and capacity building provided to developing country parties, as well as on climate finance mobilised, and that other countries “are encouraged to do so”. This information on support needs is included in various documents that have been prepared inside the UNFCCC framework (e.g. BURs, NCs, NAPAs, TNAs and INDCs) as well as outside (e.g. Strategic Program for Climate Resilience - SPCR, national climate funds). | C20: TRUE
... A38: 693d90b8de8af9a2e02231644a613426 | B38: Between 2013 and 2035, this investment would avert an estimated 147 million child deaths, 32 million stillborn deaths and 5 million maternal deaths. Yet more than 100 developing countries lack the civil registration and vital statistics (CRVS) systems needed to generate accurate birth and death data. That figure includes 39 per cent of children in sub-Saharan Africa and 44 per cent of children in South Asia. In the absence of reliable data, estimates for child mortality in countries lacking CRVS systems are based on a sophisticated statistical model using survey responses, census information and other sources. | C38: FALSE
A39: a33ed0dba09a2ffca4f24943e4fff696 | B39: The following chapter examines policy coherence and the importance of local strategies to job creation. This does not necessarily correspond to the municipal level, where the public employment service has its antennas. Such municipal offices are often merely delivery agencies with low critical mass and strategic capacity, except in urban centres. | C39: SKIP | D39: I guess I'm trying to be consistent here but given the number of such cases it is probably assumed that they are relevant
A40: 29eff581258b80edb918583680aba4f0 | B40: Cyberjaya in Malaysia was built between the new national airport and Kuala Lumpur, with fast road and rail links to the airport and high quality communications infrastructure to attract international ICT companies. Biotechnology is one sectoral focus -often fostered by regional biotech strategies. In Germany, regions developed strategies as part of their participation in the national BioRegio initiative. North Carolina State University’s Centennial Campus is being developed around four main technologies which lie at the heart of the university’s strategy - IT, genomics/biotech, advanced materials and environmental technologies. The different objectives can work against each other, such as those relating to innovation and technology transfer being undermined by commercial expediency in filling space. The strictness of criteria for entry will be weighed against the market premium for space rental based on tenant quality. | C40: FALSE | D40: It just mention infrastructure, also along with rich countries
A41: a0aa9ee0af0fcbc1161c26d11abe343d | B41: However, the lack of clarity about the distinction between climate change and development is one of the factors that has led to distrust between developed and developing countries, fuelled by concerns about additionality and the potential for competition between climate finance and development finance for a limited amount of international public finance. Development finance in the form of Official Development Assistance (ODA) increased steadily from the end of the 1990s up to 2010. In 2015, net official development assistance (ODA) flows from member countries of the Development Assistance Committee (DAC) of the OECD totalled USD 131.6 billion. | C41: TRUE
A42: e531eef8faee34e7dde0dc1fc64b386f | B42: The growing capacity of large national agricultural systems in Brazil, China, India and South Africa, for instance, has generated South-South cooperation aimed at benefiting countries with limited resources, by allowing them to adopt or adapt the technologies of the countries with large agriculture systems, which are typically less capital-intensive and have less intellectual property rights protection. Many of the current agricultural practices have relied on cheap energy and abundant water and land, and are a leading source of greenhouse gas emissions. These practices are now proving unsustainable for the environment and health. | C42: TRUE
A43: a5b0f691bf38ae1ba9b11ce474551016 | B43: Delivering on SDG 14 requires teamwork and a spirit of partnership among diverse stakeholders from many nations and sectors. The oceans cover almost three quarters of the Earth’s surface, storing one third of all the carbon emissions stemming from human activity. They are part of the solution, and we must make them a key focus of our efforts to cope with and mitigate climate change. | C43: FALSE
A44: a41c5511205aa6919bd9e6c0135c0e19 | B44: Deliveries to millers increased from 1.8 million tonnes in the 2000/01 marketing year to 4.1 million tonnes in 2010/11. Due to the relative simplicity of milling and the scalability of investments, it became an attractive activity for local entrepreneurs. Mills actively procure wheat either directly from farmers or through local traders. Almost half of Kazakhstan’s flour is produced by mills in the northern grain region. | C44: FALSE
A45: dc3b6d73253284451159a5e80f17f10d | B45: Building national capacities and international cooperation in these areas will be important. The world needs a big push—one that is public investment-led, based on international development cooperation, and capable of catalysing private sector investment and innovation so as to sustainably transform the energy system. It is recognized that the fulfilment of official development assistance (ODA) commitments is crucial. Innovative financing mechanisms can also make contributions to developing countries in respect of mobilization of additional resources for financing for development. | C45: TRUE
A46: 1edda33e74fb408587cb75092db9c826 | B46: Agricultural production expansion in LDCs since the early 1980s has occurred partly as a result of extensive growth, i.e. the expansion of the area used for agricultural production. In LDCs as a group it has grown by 10 per cent, slower than in ODCs, while in developed countries it actually contracted by 11 per cent. The extension of agricultural land use has been strongest in African LDCs and Haiti and in island LDCs. | C46: FALSE
A47: 40c1e663bf9eafcd5f47c74f01059e99 | B47: The WTO's specific contributions to the SDGs also include: ensuring access to affordable medicines in developing countries (SDG 3.b): implementing the principle of special and differential treatment to help reduce inequalities (SDG 1Q.a): and ongoing discussions on eliminating subsidies that cause overfishing and overcapacity (in order to help achieve SDG 14.6). In addition, the WTO's work on the reduction of tariff and non-tariff barriers on environmental goods and services can facilitate the diffusion of green technologies and therefore directly contribute to environmental sustainability. In this way, the WTO can ensure that the multilateral trading system contributes to building a more favourable global environment for inclusive growth and development. Over the past twenty years, international trade has undergone major changes due to a variety of economic, political and technological factors. Undoubtedly, one main leading factor of change has been the unprecedented pace of technological innovation, which has transformed traditional ways of conducting trade. Advances in ICTs have led to reduced costs and increased speed and efficiency of economic transactions, with significant productivity gains for the global economy. | C47: TRUE
A48: 6e2e95032e9349d8e0e89ae58e1e1f2b | B48: The Programme was subject to socio-economic evaluation and strategic environmental assessment. It was approved in December 2007 and ten hydroelectric power plant locations were selected, out of the 25 potential sites initially identified. The ten plants are to be located in the basins of the Rivers Douro, Vouga, Mondego and Tejo. | C48: FALSE
A49: 9b93f14a7860f878ece456a4d6e53656 | B49: Public environment-related R&D expenditure has been more or less constant as a share of public R&D spending in OECD countries. The development and diffusion of environmental technologies, as measured through patent data, is generally increasing across countries in all areas of importance to green growth. Yet progress is uneven across countries, and is unlikely to deliver major changes in key environmental domains (OECD, 2014a). Given that a large majority of “green” innovations are developed in a small number of countries, achieving greater global diffusion will be essential. | C49: TRUE
A50: 00d1f63db99df50cb6e61519d2a32f50 | B50: This technology bank for the LDCs was officially established on 23 December 2016, through the adoption of the UN General Assembly Resolution A/71/L.52. In addition, ITU's Membership recognized the importance of ICTs for LDCs by adopting specific targets for the LDCs in its Connect 2020 Agenda (ITU, 2014). Target 2, on inclusiveness, includes specific targets on household access to ICTs, Internet use, and affordability in the LDCs. Most have been primarily based on basic, low-bandwidth mobile cellular technologies. | C50: TRUE
A51: 552cabc214cd1694a4e2bcf9e53e320b | B51: It is important that the indicators align to the same framework for a full and comprehensive analysis to be made. All Nordic statistical offices are currently working to establish regular routines to produce and disseminate these statistics. Rather than to dig deep into the intricacies of a green GDP, the thrust of the effort is on developing a Nordic set of already existing indicators and measures, which relate to the SEEA Central Framework. This can be used besides GDP, as a satellite environmental account, that could be combined with traditional SNA national accounts and provide input for thorough, transparent and reliable analysis of the interplay between economy and environment. A common Nordic effort in this field would be a path-breaking contribution to the follow-up of the new UN sustainable development goals. | C51: TRUE
A52: 0706f7ce87c41745bfc91ccdae504a2d | B52: Young people and adults are entering, staying, and ending partnerships in ways different from previous generations, and education and services must respond to these changes. Young people need services between their first sexual experiences and when they marry. Services and information should be made available to adults who are separated from their partners or in new partnerships later in life. | C52: FALSE
... A61: 8825b99572daacb64c87ee7526df3666 | B61: In September 2015, President Xi announced additional commitments of USD 2 billion for South-South co-operation and to implement the SDGs (IDS, 2016). Moreover, Chinese investments in Africa are expected to increase: the Johannesburg Action Plan for comprehensive strategic and co-operative partnership with Africa provides for USD 35 billion in concessional loans and credits in 2016-2018, as well as USD 10 billion for the China-Africa Production Capacity Co-operation Fund, it also increases in the existing China-Africa development fund (for equity investment) from USD 5 billion to USD 10 billion. China's main priority sectors are public facilities, industry and economic infrastructure. | C61: TRUE
A62: 1ca7b29c9b1b93e03b31fba69ed9f4a5 | B62: A growing number of inter-ministerial mechanisms have been introduced to increase policy coherence and enhance implementation. The scale and pace of these changes has made it difficult to ensure that high quality projects were identified and implemented, that consultation with the public and local authorities was conducted according to the spirit rather than the letter of the law, and that sufficient capacity for policy implementation was developed, particularly at the local level. The enactment of so many laws and regulations in a comparatively short period of time also resulted initially in the business community facing a complex set of environmental requirements, though this has now improved. | C62: SKIP | D62: Should coherence be intergovernmental?
A63: 22a8c8ad7fca121559996cf5be31d969 | B63: The international community has created processes for monitoring progress at the regional and global levels, and for countries to exchange policy experiences, to learn from each other, and to coordiante their policies where appropriate. The present chapter contributes to this effort by analyzing how the current innovation policies of Kyrgyzstan contribute to the country’s national sustainable development priorities, comparing current policies to international good practice, and recommending policy reforms that could further encourage innovations contributing to sustainable development. The present chapter focuses on the other two pillars of sustainable development, i.e. environmental sustainability and social inclusiveness. However, it should be noted that failures to address unsustainable practices has a very real economic cost. While no estimates of this cost are available for Kyrgyzstan at present, the World Bank has for instance estimated that for neighboring Tajikistan the direct and indirect economic damage caused by environmental degradation may be as high as 8 percent of GDP.90 Thus the key to sustainable development is to achieve all three dimensions together, rather than achieving one at the expense of the others. | C63: TRUE
A64: 2e15e98e0cd6e9bd8088c06063ae66d6 | B64: The Sendai Framework for Disaster Risk Reduction 2015-2030 outlines clear targets and priorities for action to prevent new disaster risks and reduce existing ones. In the latest reports (2017-2018) from 70 countries, 67 had strategies that were aligned to some extent with the Sendai Framework. The biggest challenges are investment in disaster risk reduction for resilience and promoting policy coherence between the SDGs and climate change. | C64: TRUE
A65: 5e5dbac2056edc34caa6e204bbe0d5b4 | B65: The paper reports a study that investigated the construction of a common identity in an online Italian forum of psychologists based on asynchronous CMC. Discourse analysis was carried out on 20 discussions, and three Interpretative Repertoires were identified: (i) Professional Boundaries, (ii) disempowered psychology and (iii) psychology and health, which refer to three recurrent modalities of constructing the psychological profession. The study suggests that a framework drawing on social constructionism and Bourdieu's critical theory can help understand some aspects of identity in, and across, communities of practice. The main conclusion is that analysing critically how identities are constructed in learning environments, virtual or not, allows reconsidering the role of the cultural context in the production of those identities. | C65: FALSE
...

Sheet Jean-Baptiste
A1: Text ID | B1: Text | C1: SDG 17 Label | D1: Comments (optional)
A2: ad9ed17a58ac2d6a4d13b3bafcca8177 | B2: As a result of the Busan Declaration, the Global Partnership for Effective Development Co-operation (GPDEC) was created in 2012. Several initiatives exist in the framework of the GPDEC that are committed to advance specific commitments for effective development co-operation, including the Partnership on Climate Finance and Development. This voluntary initiative fosters country-level actions by promoting good practice and knowledge sharing on mainstreaming climate finance into development planning and more effective ways to use climate finance. | C2: TO DO
A3: dc3b6d73253284451159a5e80f17f10d | B3: Building national capacities and international cooperation in these areas will be important. The world needs a big push—one that is public investment-led, based on international development cooperation, and capable of catalysing private sector investment and innovation so as to sustainably transform the energy system. It is recognized that the fulfilment of official development assistance (ODA) commitments is crucial. Innovative financing mechanisms can also make contributions to developing countries in respect of mobilization of additional resources for financing for development. | C3: TO DO
