Workbook

Sheet Info
B2: Hello 👋
B4: Welcome to the labeling exercise for SDG 13.
B5: The objective of this exercise is to label 100 texts in terms of their relevance to SDG 13.
B7: Your Labeling Sheet
B8: You have your own personal sheet for assigning the labels. You will find it by clicking on your name in the list at the bottom of this page.
B9: Each sheet has the same 100 texts, but the order in which they appear has been randomized.
B10: Later on, we will put everyone's labels side-by-side. This will help us identify texts with high and low alignment.
B11: At our next meeting, we will discuss the texts where we have disagreements and see if we can reach a consensus for the "true" label for every text.
B12: Please resist the temptation to look at other people's labels until you are done labeling. 🙂
B14: Explanation of Labels
B15: On your personal sheet, you will find the text in column B.
B16: Column C contains a drop-down for picking the appropriate label. The options are:
B18: TRUE | C18: This text is relevant to SDG 13
B19: FALSE | C19: This text is not relevant to SDG 13
B20: SKIP | C20: You can use this if you are not sure about the label
B22: If you want, you can put any comments in column D.
B24: Instructions for Labeling
B25: The text should be annotated as SDG 13 only if:
B27: 1. The text addresses SDG 13 or one of its targets
B28: See the official definitions of SDG 13 and its targets below ("SDG 13 Description & Targets").
B30: AND
B32: 2. The text addresses SDG 13 or its targets directly:
B33: - the text should be directly relevant to SDG 13 or to achieving SDG 13
B34: - if a text only has an indirect or implicit relevance, it should not be labeled SDG 13
B36: AND
B38: 3. The text addresses SDG 13 or its targets specifically:
B39: - the text should be specific to SDG 13 and its targets
... B48: SDG 13 Description & Targets
B49: SDG 13 | C49: Take urgent action to combat climate change and its impacts
B50: Target 13.1 | C50: Strengthen resilience and adaptive capacity to climate-related hazards and natural disasters in all countries
B51: Target 13.2 | C51: Integrate climate change measures into national policies, strategies and planning
B52: Target 13.3 | C52: Improve education, awareness-raising and human and institutional capacity on climate change mitigation, adaptation, impact reduction and early warning
B53: Target 13.a | C53: Implement the commitment undertaken by developed-country parties to the United Nations Framework Convention on Climate Change to a goal of mobilizing jointly $100 billion annually by 2020 from all sources to address the needs of developing countries in the context of meaningful mitigation actions and transparency on implementation and fully operationalize the Green Climate Fund through its capitalization as soon as possible
B54: Target 13.b | C54: Promote mechanisms for raising capacity for effective climate change-related planning and management in least developed countries and small island developing States, including focusing on women, youth and local and marginalized communities
B55: Click here to see all other SDGs and targets.
B57: Labeling Sheets
B58: Please click on your name to access your personal labeling sheet. Names are listed in alphabetical order.
B60: Name | C60: Progress (will update automatically)
B61: Finn | C61: =IFERROR(__xludf.DUMMYFUNCTION("SPARKLINE((100-COUNTIF(INDIRECT(B61&""!C:C""), ""TO DO""))/100+0.01,{""charttype"",""bar"";""max"",1.01;""min"",0; ""color1"", ""#4285f4""})"),"") | D61: =(100-COUNTIF(INDIRECT(B61&"!C:C"), "TO DO")) & " / 100" -> 100 / 100
B62: Gib | C62: =IFERROR(__xludf.DUMMYFUNCTION("SPARKLINE((100-COUNTIF(INDIRECT(B62&""!C:C""), ""TO DO""))/100+0.01,{""charttype"",""bar"";""max"",1.01;""min"",0; ""color1"", ""#4285f4""})"),"") | D62: =(100-COUNTIF(INDIRECT(B62&"!C:C"), "TO DO")) & " / 100" -> 21 / 100
...

Sheet Finn
A1: Text ID | B1: Text | C1: SDG 13 Label | D1: Comments (optional)
A2: c06441e414c0053d15771b0a7ad88b5c | B2: Encouraging systematic reporting on climate finance at a disaggregated level (such as activity-level information) could also help improve transparency, as well as accessibility of information. Reporting in the form of a standardised database with common variables and classifications (such as exchange rates) would also help to improve consistency. In this context, the UNFCCC could usefully draw on the experience from existing statistical systems on international flows, such as the OECD DAC. | C2: TRUE
A3: ff2679ddf016ef04e163c6898249b438 | B3: The Policy Forum brought together policy-makers and experts from 25 OECD countries, from international organisations and from the private sector to discuss progress, common challenges and successes in the development of national adaptation strategies (OECD, 2012b). The original version included additional European countries which are excluded from the updated table, and also did not include four OECD countries (Chile, Israel, Luxembourg and Turkey) which are included in this analysis. Most OECD members are Annex I countries, with the exception of Chile, Israel, Korea, Mexico. Turkey is an Annex I country, but has only published one NC. The assessment of the scope of discussion is based on the level of attention paid to the topic, classified as: i) extensive, ii) limited, or iii) lacking. | C3: SKIP | D3: not clear if climate
A4: 4cf9ad44865017149316746a9793ad1b | B4: However, when such actions provide both private and public benefits, the public sector may play a role in how these are developed. This report aims to establish a framework to help identify specific actions that governments could take in this respect and that could avoid sending signals leading to non-adaptation or maladaptation. This report begins with a review of national adaptation strategies for the agricultural sector in OECD countries and highlights different approaches undertaken by governments. | C4: FALSE
A5: 7ec93941c63752701a2ef7870e4c4257 | B5: Many of the diverse carbon-related investment ideas in the CRGE are practicable and financially sound. While such ideas have not yet reaped rewards in terms of significant climate funding, they have improved the confidence of Ethiopia’s bilateral donors, some of whom have supported the CRGE process, but more of whom are considering ways to help Ethiopia address the evident implementation and capacity challenges. While the current focus of the CRGE is usefully tactical, if the singular focus on achieving MIC status and GHG reduction were to continue beyond an initial carefully-monitored phase, that focus could bias against future options for wellbeing. Sustainable development demands, ultimately, that linked systemic problems are tackled with systemic improvements to institutions and governance, and not just with investment projects. It requires changing the way that routine government expenditure is channelled, and not just with attracting new sources of finance. It demands attention to the range of environmental opportunities, and not just with GHGs. | C5: TRUE
A6: b5591155854d75dc564575f388eacfe7 | B6: The Agreement lists possible vehicles through which an adaptation communication could be submitted (Article 7.11), while leaving the form and timing of an adaptation communication open. The Paris Agreement also stresses that adaptation reporting should avoid creating any additional burden for developing country Parties. At a national level, identifying and collating information could help a country communicate its priority needs and actions, identify progress towards national goals, highlight the need for international support, and better co-ordinate and communicate actions and funding within the country. | C6: SKIP | D6: not clear if climate
A7: 44272fd9a3e9cb89d4370b435c53bcc7 | B7: Examples of capacity elements for each of the three levels are summarised in Table 2.2. A Practical Guide for Planning, implementing, and Assessing Capacity Building of HIV/AIDS Monitoring and Evaluation Systems, Office of the Global AIDS Coordinator, United States Government, Washington, DC. The objective of the assessment was to identify the strengths and weaknesses of the government’s approach to MfDR. The assessment found that there was a significant lack of capacity to monitor and evaluate public policies in all sectors. Further, the majority of sectors lacked the capacity to analyse statistical data and to use monitoring and evaluation findings to inform decision-making processes (Government of Ghana, 2012). | C7: FALSE
A8: 496987454c498ea9a52f60b40e4abadb | B8: Examples of this are the initiatives undertaken by the Chilean Government following the 2010 earthquake and the Emergency Grant distributed to persons affected by disasters by the Ecuadoran Government. In terms of policy proposals, an interesting case is Trinidad and Tobago, where an economic subsidy for home repair is available to the recipients of non-contributory pensions. It would also be advisable to intensify efforts to expand the population eligible for cash transfers following a disaster, to include families that do not have older members or school-age children. The aim is for those families to be eligible for a cash transfer in adverse situations not of their choice, at least on a temporary basis. | C8: TRUE | D8: target 13.1
A9: 2ce23ba1ca724800a7753d7728b03791 | B9: The discussion covers a variety of international and national actors, including development finance institutions, international climate funds, governments and relevant government agencies. Data regarding global finance flows are mostly drawn from the Climate Policy Initiative (CPI) reports as they represent the most comprehensive source of such flows to date. Second, the paper focuses on the regional landscape of climate finance in the Asia-Pacific region, with particular attention given to active climate funds, multilateral development banks, the distribution of climate finance across countries, and national-level initiatives. | C9: TRUE
A10: 701b01382264358af6eecebbabe5d716 | B10: Authorship is usually collective, but principal authors are named. Some programmes have multiple donors, in which case they have been recorded under the agency that supplied the document. Some projects and programmes only have ex ante evaluations, others have ex ante and ex post evaluations as well as a number of intermediate reviews. This is in part due to the timing of the projects. | C10: FALSE
A11: 26443f27488420a4af1a208fd73f5bbd | B11: In 2015, the geographic scope was expanded to include small island developing States in the Pacific. It contributes to the narrowing of capacity gaps through regional and South-South cooperation, sharing of resources and the development of an integrated regional warning system comprising a network of collaborative centres. Civil society innovations and business sector initiatives. | C11: FALSE
A12: 39e8f1930335d2a3b6161db61e538edc | B12: There was some causality to this correlation in that opportunity for corruption in those states was bred by the inflow of large sums of relief funding and lucrative postdisaster construction contracts (ibid.). In sectors and localities, corrupt practices can increase disaster risk by corroding a culture of compliance that is key to the effectiveness of codes, standards and similar regulatory mechanisms. The construction industry is one of the sectors most critical to disaster risk management and also one of the most prone to corruption (Transparency International, 2005). | C12: FALSE
A13: df44786a351fe3f62c262366d0e30b62 | B13: The data used include results from 91 studies with 1 722 estimates of changes in crop yields by Challinor et al., There are wide variations among the studies, in terms of time-frame, crop coverage, crop and climate models, and emission levels. Some studies include the effects of adaptation measures, but others do not. | C13: TRUE | D13: fight climate impacts? weak
A14: 69dc28d3d07ccb48f87aa145b030b6a4 | B14: This also helped the analysis to be done in the very short time available - from February 2011 to the Durban Climate Change Conference (COP 17) at the end of the year. Over 50 Ethiopian experts from the selected sectors generated data, which the external consultants calculated BAU emissions projections for sectors that were identified to be higher sources of emissions (Table 2) and came up with possible abatement measures in those sectors and their individual marginal abatement cost. Projections for 2025 demonstrated that the current pathway for economic development will increase GHG emissions by more than 150%. | C14: TRUE
A15: 6ffe9bf74c3883ac32ff1d5b3f80cb59 | B15: It would also be helpful to have some degree of international convergence on the approach to be used for calculating national BAU baselines. Parties could agree the time frame and GWPs or other GHG-equivalence metric to be used for commitments. It is possible that bounded flexibility could also be negotiated for other dimensions of mitigation commitments, depending on the varying national circumstances of countries. | C15: TRUE
A16: 59fcd1290730dc297569125d61852dec | B16: The IIC mentioned above has identified an unexpected benefit related to their programming and hiring practices, which gives some preference to applicants from local indigenous communities. What IIC has observed is that in addition to individual benefits related directly to their programme involvement, a meaningful number of these former staff and students have subsequently gone on to influential positions in their communities. With such relationships between the centre and nearby community leaders established over time, IIC is in a very good position to support broad and powerful community-based ESD within traditional channels. This programme has drawn participants from school-based eco-clubs which are common in the country, and is part of a tiered approach to ECHO’s work with communities that also includes the establishment of eco-teams involving adults and community leaders to support student and youth activities (Kaieteur News 2010). | C16: FALSE
A17: 8c27ff6209202070dbd763c6241ad2bd | B17: Likely that different Parties will develop national and sub-national institutions. One option is that the current institutional arrangements shall support Patties in implementing adaptation. Another is that new international institutional arrangements such as a subsidiary body for adaptation or adaptation registry should be developed. | C17: SKIP | D17: not enough context that it is about climate
A18: b6ff332fb8f8c8f1c7028fa5938d2382 | B18: Exercise Report, IOWave 14. Most of the gaps here - such as improving communication among key actors, participation of local communities and performance assessments - relate to good governance. Gender issues as well as the special needs of other vulnerable groups such as pregnant women and older persons also need to be taken into account. International standards proving common alert levels and colour codes in a multi-hazard approach could help facilitate this. But it is important also to build the political will and institutional commitment to ensure the necessary resources and coordination. Integrate the concept of ‘early warning as a public good’ into national planning, policy and decision-making. | C18: FALSE
A19: 77e831e56461b254b01dcc2544f226f1 | B19: A number of factors, however, can complicate sharing lessons both within and between organisations. These include lack of formal co-ordination and advanced planning, uncertainty on how to organise information in a useful format, and difficulties in making context-specific findings relevant to other interventions (e.g. see previous discussion on RCTs). For instance, an independent review of the CIFs highlighted that the incorporation of information sharing and lesson learning in interventions varied significantly by fund (ICF, 2013). | C19: FALSE
A20: 34a99e6f5fa914f7a0242511d1a35964 | B20: Since the late 1990s, the Government of Ethiopia has had clear aspirations for broad-based sustainable development and poverty reduction, as evidenced in a series of strategies such as the Sustainable Development for Poverty Reduction Programme (SDPRP, 2000-2004), the Plan for Accelerated and Sustained Development to End Poverty (PASDEP, 2005 to 2009), and the Growth and Transformation Plan (GTP, 2010-2014). The effects on the economy of the first two strategies were judged to be very significant, with strong economic growth, poverty reduced, employment increased, and some exports flourishing (MoFED, 2002,2005). Its clear link to the GTP, notably its reassertion of the need to achieve middle-income status, means that it builds on previous decisions about where national development is headed. | C20: FALSE
A21: 39089c8f728768b345d5366230965a8b | B21: Ministers and other senior policy officials can champion the importance of monitoring and evaluation and ensure that findings contribute to a transparent, evidence-based adaptation policy planning and implementation process (Segone, 2008). There is also scope for greater exchange among countries of lessons learned on effective adaptation approaches and on methods used to monitor and evaluate them. Answerability is primarily based on political will to justify decisions and actions based on the monitoring and evaluation of adaptation interventions. Enforceability, on the other hand, refers to the ability of governments to ensure that national policy commitments agreed upon (e.g. in their annual or periodic development plans) are being met and that corrective measures are undertaken when they are not. | C21: SKIP | D21: unclear if climate
A22: b3c8363c053550e71a1ce55c73052786 | B22: The integrated nature of the public policies is based (among other factors) on a correct definition of the beneficiaries in socioeconomic and territorial terms, which depends on the quality of disaggregated data available at the household and territorial levels, to be able to distinguish zones or settlements. The institutional framework needs the capacity to identify households and localities that are highly exposed and vulnerable to disasters, in an efficient and planned way, so that they can be included among the priority objectives of public policies aimed at increasing resilience to such phenomena among people and communities. Development Policy Review, vol. | C22: TRUE | D22: target 13.1
A23: d07386044818372985bffc36a8bf81f3 | B23: Given the variety of technologies, sectors, and scales of technology-transfer interventions, it would be difficult to have a single meaningful indicator that could be aggregated across multiple projects. For instance, the Global Environment Facility’s (GEF) indicator for technology-transfer interventions is qualitative in nature, focusing on capturing the type and maturity of technologies that are being transferred. Mitigation-focused interventions generally seek to reduce GHG emissions directly (e.g. by improving fuel combustion efficiencies) or indirectly and/or in the longer-term (e.g. by increasing awareness about low-GHG technologies). Projects seeking to increase adaptive capacity and resilience can take a number of forms (e.g. awareness and education programmes, institutional reforms, physical infrastructure projects) and have results that accrue at local, regional, or global scales and over different time horizons. | C23: TRUE
A24: 878040846cfddc6b0f3cd28e1cf7d045 | B24: Equity usually attracts investors that are looking for higher risk. Public investment per capita in 2012 fell in 15 out of 33 OECD countries, compared to 2007 (OECD, 2014a). The low-carbon transition will require the large-scale mobilisation of all sources of private sector investment and finance (Corfee-Morlot et al., | C24: TRUE
A25: 8f649ca15674f420fb2ea6554e6ed03d | B25: Nonetheless, all 11 countries are eligible to receive official development assistance (ODA) from OECD DAC member countries. They also have access to some of the funding sources under the Financial Mechanism of the Convention2 (e.g. Global Environment Facility, or the GEF). Exceptions include the Least Developed Countries Fund operated by the GEF since none of the EECCA countries is categorised as a Least Developed Country under the UN. While the data analysed in this chapter is on climate-related development finance committed in 2013 and 2014, the Board of the Green Climate Fund approved two project proposals in the EECCA region at its 13th meeting in June 2016 (one in Armenia and the other in Tajikistan and Uzbekistan). | C25: TRUE
A26: 573084d18b440c49006f1ae5691b785f | B26: The low-carbon transition will require mobilising of all sources of public and private sector investment and finance, including institutional investors. Governments need to use their scarce resources to trigger large-scale private sector investment in activities otherwise unlikely to attract sufficient private funding. However, some financial systems regulations hinder the allocation of longterm finance to low-carbon infrastructure investments. | C26: TRUE
A27: 4d61af08bc277e91c8f6e284f03ee85d | B27: Countries pointed out that given the small number of officials working on climate finance in national ministries, just one staff member working on tracking and monitoring would be a large proportion of their human resources. Developed countries have committed to provide financial support to cover the full cost incurred by developing countries in complying with reporting duties towards the UNFCCC16. For example, as part of national Climate Public Expenditure and Institutional Reviews (CPEIRs), a group of international organisations and research institutes are collaborating to assist countries in tracking climate finance across national budgets. It was widely recognised that tracking flows to a certain level of granularity is also a pre-condition for monitoring outcomes and outputs. | C27: TRUE
A28: a3761ca30cb3fc6ab902a6cb4654005e | B28: Despite the shift in the economic structure, agriculture remains a major source of economic growth for the country, the principal source of income for the rural majority, and critical for food security for all Ethiopians. If poverty is to be reduced, and wealth created in ways in which the majority of the population can participate, then agriculture clearly has to be at the heart of any inclusive and green development strategy. More than 70% of crop land is devoted to cereal production, that area having expanded by 27% from 7.0 million hectares in 2003/04 to 9.6 million in 2011/12. More than 11 million smallholders engage in cereal production, with cereal production totalling 18 million tonnes in 2011/12. | C28: TRUE | D28: could be non-climate related
A29: fb8a400d6dce461b88707fa0f4d02f39 | B29: The GCF Board has set a target of committing US$2.5 billion in funding in 2016, in June 2015, nine projects with a value of US$257 million in GCF resources and total cost of US$585 million, were approved. The low approval level is indicative of the challenges the GCF is facing as a new institution, the capacity constraints of the direct access entities and at the national level, staffing constraints in the GCF Secretariat, and the rigorous project preparation requirements that did not distinguish between project type and size. At its June 2016 meeting, the GCF Board approved the operational guidelines for its Project Preparation Facility and a simplified procedure for micro-scale and small-scale funding proposals that are assessed as low risk or no risk. These new procedures should accelerate the project approval process. | C29: TRUE
A30: 9941b10e52bd2df1557343a693c3cb52 | B30: For instance, Jordan’s INDC states that their mitigation and adaptation measures should be linked and also aligned with specific Sustainable Development Goals. This approach could help countries streamline their effort for monitoring and reporting given that a number of indicators to monitor progress towards SDGs and their targets might overlap with those needed for adaptation. Some countries use different timescales for different sectors (e.g. Guinea-Bissau’s and Lao People’s Republic), while about 40 countries’ adaptation components of INDCs have no mention of timeframes. Some INDCs have expressed that they will use existing systems to monitor and evaluate the effectiveness of adaptation actions (e.g. Zambia). | C30: TRUE
A31: c5a826c20b377bf1adb012a8fb56b9de | B31: Regions and municipalities are also responsible for the implementation of much of Finland’s National Adaptation Strategy, and approximately a third of regions/municipalities had an adaptation strategy by 2012 (Luhtala, 2012). Some climate funds have specific “windows” for funding local adaptation actions. For example, the Bangladesh Climate Change Resilience Fund (BCCRF) includes a USD 10.4 million window for a “Community Climate Change Fund” which is to provide grants for community-based projects (BCCRF, 2012). | C31: TRUE
A32: d3e888a7bb7201bc4d6a1e4f09015bf7 | B32: Table VIII.l shows the breakdown of types of disaster in the different subregions of Latin America and the Caribbean. Studies by Blaikie and others (1996) and by Cutter, Boruff and Shirley (2003) clearly identify the vulnerability factors that contribute to the occurrence of disasters. These include poverty, urban expansion into areas unsuitable for building, economic dependency on agricultural activities, the scant existence of financial insurance policies covering disasters, and growing environmental degradation. The consequence of this is that developing countries are highly likely to suffer extreme weather events, high temperatures, and the disruption of ecological systems that are bound to generate new risks for life, settlements, public-service infrastructure and production, among other things (Lo Vuolo, 2014, p. 19). | C32: TRUE | D32: target 13.1
A33: 74f5f26b90fc869a2a9aae8c43b48da1 | B33: However, the ability of an intervention to mobilise or leverage financing does not necessarily imply effectiveness in a broader sense. For instance, some analysis has highlighted the possibility that high leverage or mobilisation rates may indicate a strong perception of commercial viability amongst private investors who may have invested without public intervention (Stadelmann et al., In addition to its narrow focus, one of the difficulties in using financial mobilisation as an indicator in assessing effectiveness is that there are wide differences in how mobilisation and leverage are defined and measured between different institutions (see Caruso and Ellis, 2013 for a more detailed discussion). Even in the absence of methodological differences, mobilisation rates will vary significantly across financial instruments, technologies, sectors, and countries (UN AGF, 2010, Smallridge, et al., | C33: FALSE
A34: f78857097015f3464577232fe7af3987 | B34: Article 13 also establishes a two-step review and consideration process. The first step is a technical expert review of information on mitigation and support provided. The review will identify areas of improvement for the Party, review consistency with the modalities and guidelines to be developed under Article 13.13, and assist developing country Parties to identify capacity-building needs (for those that need it). | C34: SKIP
A35: 991424ae3d1a00619b4d51308b5775d9 | B35: It also uses the term “recipient” for the country, programme or activity the funds are being channelled to. Such terms may be less relevant for developing countries that provide support, given the different nature, modalities and responsibilities applicable to South-South co-operation. Countries are not viewed as donors and recipients, but providers and partners.22 Not all countries agree with the “boundaries” of ODA and OOF as defined by the OECD or view them as applicable (OECD, 2015b, Walz and Ramachandran, 2011). | C35: FALSE
A36: caa44e92110e395863352c6e68e8aa87 | B36: Depending on the results of this risk assessment process, they may decide that it is necessary to implement explicit risk management strategies. Each successive level builds on the results of the preceding one. The key question for them is what their risks are now and how these will evolve over time. | C36: FALSE
A37: 5e242763926d5068bfc1388cbd6beda2 | B37: There are now stand-alone goals on inequalities, cities and human settlements, energy, climate change, sustainable consumption and production, and the protection of marine and terrestrial ecosystems. This broad agenda reflects human rights principles and standards and recognizes the interlinkages between different areas of development and the importance of environmental and climate protection for poverty reduction and human well-being. Nevertheless, the agenda is fraught with tensions both between different goals and between its normative aspirations and the suggested means of implementation that largely rely on trade, private finance and public-private partnerships (chapter 7). | C37: TRUE
A38: 555d67cba1d1d1935b39ec487291ffe2 | B38: However it is also vital to restore the communications infrastructure as a whole. The internet, however, operates on the principles of packet-switching in which individual packets of information that make up a message can take any one of multiple routes according to availability. This level of redundancy makes it inherently more flexible and resilient. | C38: FALSE
A39: a3c29985fccdc701de3acc3073d3fafa | B39: With per-person GDP of only $380‘, the proportion of the population below the poverty line in 2010/11 was 30.4% in rural areas and 25.7% in urban areas. Poverty has declined substantially according to the national Household Income Consumption Expenditure Survey. Between 2004/05 and 2010/11, income inequality measured by Gini Coefficient was changed little - from 0.3 in 2004/05 to 0.298 in 2010/11.2 While urban inequality declined from 0.44 to 0.37, rural inequality increased from 0.26 to 0.27 (MoFED, 2012a). | C39: FALSE
A40: abdef9b2251fa5f2e0e0852b0d27c604 | B40: This work stands out because of its emphasis on literature, culture and citizenship, as opposed to the more directly environmental approach to ESD common in much of the Caribbean. Also notable in this regard is an undergraduate course in teaching Caribbean poetry, which was designed in collaboration with Cambridge University, and integrates a sustainability focus through a strand on literature and the environment. In addition to these courses, the university is also exploring ESD possibilities campus-wide. | C40: FALSE
...

Sheet Gib
A1: Text ID | B1: Text | C1: SDG 13 Label | D1: Comments (optional)
A2: d77bc6dc6840b019fea62483a9dd73bb | B2: Rio markers could move towards a more exact definition and quantification by moving away from the binary classification approach and towards a percentage allocation for each project. The DAC could follow the lead of the World Bank Group, as they are currently working towards tracking the adaptation and mitigation ‘co-benefits’ of their investments, based on a percentage of each sub-sector in each investment, across their entire portfolio and all core funding sources.60 Australia is also testing such a system. For the definition of the Rio marker for adaptation: www.oecd.org/dataoecd/l/45/45303527.ndf (page 5). These will be based on a series of vetted investment activity typologies. | C2: TRUE
A3: 74f5f26b90fc869a2a9aae8c43b48da1 | B3: However, the ability of an intervention to mobilise or leverage financing does not necessarily imply effectiveness in a broader sense. For instance, some analysis has highlighted the possibility that high leverage or mobilisation rates may indicate a strong perception of commercial viability amongst private investors who may have invested without public intervention (Stadelmann et al., In addition to its narrow focus, one of the difficulties in using financial mobilisation as an indicator in assessing effectiveness is that there are wide differences in how mobilisation and leverage are defined and measured between different institutions (see Caruso and Ellis, 2013 for a more detailed discussion). Even in the absence of methodological differences, mobilisation rates will vary significantly across financial instruments, technologies, sectors, and countries (UN AGF, 2010, Smallridge, et al., | C3: FALSE | D3: Could be true. The passage is unspecific about what the financial mobilization is for.
A4: efda660886221e58c1e49fa726c6be33 | B4: This links the PDNA process with the ‘building back better’ approach. This is used as a basis for developing a comprehensive immediate and long-term recovery framework and for mobilizing assistance from donors and development partners. These can use the PDNA methodological framework, and retain a sound scientific base, but need to be downscaled to meet local needs. | C4: FALSE
A5: d91641dd845973e6ab2690fe402a3b1d | B5: In contrast, the dominant market-liberal rationality sees human and natural resources as production factors to achieve economic growth as the main pathway toward welfare. As noted above, such an approach has been associated with adverse social and environmental impacts.25 Does the 2030 Agenda hold the potential for a profound transformation toward a more progressive and rights-based eco-social approach that would shift the normative hierarchy for decision making, as discussed in chapter 7? Many lower and middle income countries object to the 2°C goal, especially low-lying small island states that stress the significant risks and impacts they already face at lower levels of global warming. | C5: TRUE
A6: 97667eac56e4d03c36143e91e36f5198 | B6: Significantly fewer focus only on adaptation (4 initiatives) or mitigation (1 initiative) (see Appendix B). Several of these approaches have been found to contain various benefits in relation to climate change and agriculture, e.g. increased mitigation of emissions or larger adaptive capacity. These benefits are identified in peer-reviewed literature, and based on local experiences, on-the-ground tests, and various evaluations of such agricultural approaches and practices5. Success stories of CSA include water harvesting in the Sahel and Drought-Tolerant Maize for African farmers, the purpose of which is to make crops more climate change resilience and mitigate the GHG emissions related to agricultural production (Neate, 2013, FAO, 2017b). | C6: TRUE
A7: d07386044818372985bffc36a8bf81f3 | B7: Given the variety of technologies, sectors, and scales of technology-transfer interventions, it would be difficult to have a single meaningful indicator that could be aggregated across multiple projects. For instance, the Global Environment Facility’s (GEF) indicator for technology-transfer interventions is qualitative in nature, focusing on capturing the type and maturity of technologies that are being transferred. Mitigation-focused interventions generally seek to reduce GHG emissions directly (e.g. by improving fuel combustion efficiencies) or indirectly and/or in the longer-term (e.g. by increasing awareness about low-GHG technologies). Projects seeking to increase adaptive capacity and resilience can take a number of forms (e.g. awareness and education programmes, institutional reforms, physical infrastructure projects) and have results that accrue at local, regional, or global scales and over different time horizons. | C7: TRUE
A8: 0cd4cbb613dc281d0552a04b992a719c | B8: Further, a pilot project for a new technology may be implemented and run efficiently (and could therefore be judged to be effective at a project level), but does not meet its goal of being replicated at scale (and is therefore less effective when viewed from a national or sectoral level). The inputs to an intervention can be financial, human (e.g. information or labour), or material goods that help to achieve the strategic objectives of the intervention. Decisions on appropriate inputs will depend both on the strategic objectives of the intervention as well as local context and needs. | C8: FALSE
A9: 7ec93941c63752701a2ef7870e4c4257 | B9: Many of the diverse carbon-related investment ideas in the CRGE are practicable and financially sound. While such ideas have not yet reaped rewards in terms of significant climate funding, they have improved the confidence of Ethiopia’s bilateral donors, some of whom have supported the CRGE process, but more of whom are considering ways to help Ethiopia address the evident implementation and capacity challenges. While the current focus of the CRGE is usefully tactical, if the singular focus on achieving MIC status and GHG reduction were to continue beyond an initial carefully-monitored phase, that focus could bias against future options for wellbeing. Sustainable development demands, ultimately, that linked systemic problems are tackled with systemic improvements to institutions and governance, and not just with investment projects. It requires changing the way that routine government expenditure is channelled, and not just with attracting new sources of finance. It demands attention to the range of environmental opportunities, and not just with GHGs. | C9: TRUE
A10: 496987454c498ea9a52f60b40e4abadb | B10: Examples of this are the initiatives undertaken by the Chilean Government following the 2010 earthquake and the Emergency Grant distributed to persons affected by disasters by the Ecuadoran Government. In terms of policy proposals, an interesting case is Trinidad and Tobago, where an economic subsidy for home repair is available to the recipients of non-contributory pensions. It would also be advisable to intensify efforts to expand the population eligible for cash transfers following a disaster, to include families that do not have older members or school-age children. The aim is for those families to be eligible for a cash transfer in adverse situations not of their choice, at least on a temporary basis. | C10: FALSE
A11: dab78d37b9225afdbb7f06fe03105710 | B11: Improving access to stable and adequate sources of finance for adaptation and contributing to the building of the information systems needed to guide policymaking for climate resilience are two concrete actions where greater international cooperation is needed. Public domestic and international efforts are needed to mobilize sufficient resources and provide incentives to the private sector to invest in adaptation. This is especially important for building the resilience and adaptive capacity of the most marginalized areas and population groups. | C11: TRUE
A12: 89c55241e87651dbd5bf53b85a1372df | B12: According to recent data, costs from major flood events will likely be counted in the billions of dollars with potential serious impacts on national GDP (World Bank, 2010), as well as on the lives of poorer and marginalized communities, in particular. The international community, multilateral development banks and United Nations funds and programmes are working to support delivery of and direct access to existing and pledged international climate finance. However, international flows alone will not be sufficient to meet the growing demand for climate mitigation and adaptation finance. In the absence of an internationally acknowledged definition of climate finance, in this paper, the United Nations Framework Convention on Climate Change (UNFCCC) definition is used, which is “local, national or transnational financing, which may be drawn from public, private and alternative sources of financing” (UNFCCC, 2014a) and which target low-carbon and climate-resilient development. | C12: TRUE
A13: a3c29985fccdc701de3acc3073d3fafa | B13: With per-person GDP of only $380‘, the proportion of the population below the poverty line in 2010/11 was 30.4% in rural areas and 25.7% in urban areas. Poverty has declined substantially according to the national Household Income Consumption Expenditure Survey. Between 2004/05 and 2010/11, income inequality measured by Gini Coefficient was changed little - from 0.3 in 2004/05 to 0.298 in 2010/11.2 While urban inequality declined from 0.44 to 0.37, rural inequality increased from 0.26 to 0.27 (MoFED, 2012a). | C13: FALSE
A14: 6775da6444c36eea4ffa3fd07bd20d07 | B14: They focus on actively engaging the communities, providing space for innovation and ensuring that higher level policies and plans are adapted to local settings. The national policy framework can foster local innovation when it provides an enabling environment, for example, through the provision of social protection and regulation of market actors. Achieving the SDGs will depend on identifying the right policy mixes and governance approaches that can combine progressive public policies and environmental regulation with local initiatives and innovations in a way that promotes transformative change toward equity and sustainability. It will also depend on ensuring that the promotion of technological innovation, private sector investment and multistakeholder partnership is in line with considerations for social inclusion, participation and empowerment (chapter 7). | C14: TO DO
A15: 3dfa766f6f36763d498549844dd47646 | B15: This was agreed to by more than 130 countries and lays out agreed principles for effective development finance that also cover climate-related aid: these principles relate to country ownership, alignment, harmonisation, results and mutual accountability. The subsequent Busan Partnership on Effective Development Co-operation (2011), agreed to by 150 countries, outlines the importance of climate finance as well as extending the scope of these principles beyond aid to cover development finance and development co-operation more broadly. These include both general principles as well as those developed in the context of funds established by the UNFCCC process such as the Green Climate Fund and the Global Environment Facility. | C15: TO DO
A16: 150d07b74a3d498d523fa88ea385347b | B16: The Paris Agreement requires all Parties to undertake and communicate national mitigation and adaptation measures to respond to the threat of climate change. In addition, developed countries are required to provide and report on financial assistance, technology transfer and capacity-building support to developing-country Parties to the Agreement. For their part, developing countries are expected to provide information on the support needed and received. | C16: TO DO
A17: 1c30523b2a258cb264a1ea24664c8254 | B17: Ethiopia's first sectoral resilience strategy, which focuses on agriculture, revealed that 38 of 41 priority climate resilience options are already being carried out to some extent. This indicates that most early resilience efforts will concentrate on scaling-up and enhancing the resilience of existing measures, rather than crafting new ones. As Ethiopia's future climate conditions are highly uncertain, it will be crucial to adopt an iterative and flexible approach to building resilience. At present, Ethiopia primarily relies on disaster response financing from official development assistance. | C17: TO DO
A18: e57cc1355ac34fcde9e9705083a310bb | B18: Several underscored the importance of bilateral, regional and international cooperation in this area. Some members stressed that initiatives to counter illegal logging should be consistent with WTO disciplines, scientifically based, and not constitute unnecessary barriers to trade. Concerns were raised on the implementation costs of such initiatives and the need for capacity building in developing countries to build awareness and improve enforcement of laws to combat illegal logging. | C18: TO DO
A19: 8a5a6b031aecd8f4312d6beedc709457 | B19: This is because it may be difficult to ensure the collection of project-level information from the ultimate beneficiary of these funds (Caruso and Ellis, 2013). Such methods seek to test whether theories of change are leading to observable results and can help to overcome some of the challenges outlined with regards to causality, baselines and attribution. The design of RCTs (explained more fully in Duflo et. This allows a given policy or programme to be judged against the performance of randomly selected, similar, and actual cases that have not been subject to the intervention as opposed to assumed baselines of how the intervention’s subjects would have performed in its absence. | C19: TO DO
A20: 6ffe9bf74c3883ac32ff1d5b3f80cb59 | B20: It would also be helpful to have some degree of international convergence on the approach to be used for calculating national BAU baselines. Parties could agree the time frame and GWPs or other GHG-equivalence metric to be used for commitments. It is possible that bounded flexibility could also be negotiated for other dimensions of mitigation commitments, depending on the varying national circumstances of countries. | C20: TO DO
A21: a2deed2945173b7fb758c45538d672a9 | B21: Common sources of data include household and living standard surveys, sectoral statistics, labour force reviews and so on. Experience to date, however, has shown that data collection processes often differ and there is a lack of alignment between global monitoring needs and national reporting capacities (Paris21, 2013). The approach used by the UK for the 2012 national assessment of flood risk was to score datasets against a number of criteria to determine their statistical quality and relative strengths and weaknesses (see Box 2.1). However, such scorecard assessments can be difficult to do in practice if there is no central data repository or if there is limited co-ordination between data producers and users. | C21: TO DO
A22: 06fd29e21b58d3feba47d74236d45e53 | B22: This handbook aims to reduce the impacts of natural disasters on local coastal tourism communities. The handbook's approach builds on UNEP's Awareness and Preparedness for Emergencies at the Local Level (APELL) process, designed to create public awareness of hazards and to ensure that communities and emergency services are adequately trained and prepared to respond. | C22: TO DO
A23: 26443f27488420a4af1a208fd73f5bbd | B23: In 2015, the geographic scope was expanded to include small island developing States in the Pacific. It contributes to the narrowing of capacity gaps through regional and South-South cooperation, sharing of resources and the development of an integrated regional warning system comprising a network of collaborative centres. Civil society innovations and business sector initiatives. | C23: TO DO
A24: ec8cb5e870b86c2468c25b43b3c6098b | B24: By 2080, in Africa, an increase from 5 to 8 per cent in arid and semi-arid land is projected under a range of climate scenarios. While identifying particularly vulnerable groups globally and at country level remains challenging, it is particularly important for policymaking directed towards building climate resilience. People living in low-lying coastal areas, drylands, and mountainous and remote areas and population groups whose livelihoods rely on forest products are particularly at risk. Yet, basic information on population size, socioeconomic characteristics and risk factors which could help identify those groups remains in the form of very rough approximations. Some of those groups are difficult to reach owing to their geographical location, but the lack of basic information is also associated with an insufficiency in the resources for producing statistics at the level of disaggregation required to identify specific population groups. | C24: TO DO
A25: 8f649ca15674f420fb2ea6554e6ed03d | B25: Nonetheless, all 11 countries are eligible to receive official development assistance (ODA) from OECD DAC member countries. They also have access to some of the funding sources under the Financial Mechanism of the Convention2 (e.g. Global Environment Facility, or the GEF). Exceptions include the Least Developed Countries Fund operated by the GEF since none of the EECCA countries is categorised as a Least Developed Country under the UN. While the data analysed in this chapter is on climate-related development finance committed in 2013 and 2014, the Board of the Green Climate Fund approved two project proposals in the EECCA region at its 13th meeting in June 2016 (one in Armenia and the other in Tajikistan and Uzbekistan). | C25: TO DO
... A92: 99964ce761d15a0adc936922afb552c4 | B92: However, recognising that developing and implementing a national framework can be time-consuming and resource intensive, countries may choose to initially focus on aspects that can be monitored within existing limits of data availability and monitoring and evaluation capacity. Over time, the coverage and scope may gradually expand (GIZ, 2013). For monitoring and evaluation to contribute to learning, it is beneficial if they are based on demand for the information by those closely linked to policy-making processes. | C92: TO DO
A93: efc52dea07b2385c3c947c5398e5fa78 | B93: Tonga’s Ministry of Education, Women’s Affairs and Culture (MoEWAC) is working to seize this opportunity, getting involved in national and regional media industry-oriented workshops, in order to foster opportunities for co-operation. The ministry has worked with local media to educate them on agendas such as EFA, the MDGs and the UNDESD, and one representative has indicated that the media has become a ‘catalyst and advocate for local co-operation and contributions to sustainable development, especially at the grassroots and community level’. None of these associations are commonly made with mainstream or mass media sources. | C93: FALSE | D93: Could be true. I labelled it false because talking about sustainable development in developing countries does not always touch the climate change topic.
A94: 59fcd1290730dc297569125d61852dec | B94: The IIC mentioned above has identified an unexpected benefit related to their programming and hiring practices, which gives some preference to applicants from local indigenous communities. What IIC has observed is that in addition to individual benefits related directly to their programme involvement, a meaningful number of these former staff and students have subsequently gone on to influential positions in their communities. With such relationships between the centre and nearby community leaders established over time, IIC is in a very good position to support broad and powerful community-based ESD within traditional channels. This programme has drawn participants from school-based eco-clubs which are common in the country, and is part of a tiered approach to ECHO’s work with communities that also includes the establishment of eco-teams involving adults and community leaders to support student and youth activities (Kaieteur News 2010). | C94: SKIP
A95: 541d04aef96581fb24db13382528fe6a | B95: For initiatives where web and literature searches yielded insufficient results, organizations and experts responsible for the initiative were asked for supplementary information. As mentioned in the introduction to this report, the focus is on developing country regions, notably Sub-Saharan Africa (SSA). Throughout the report, three other regions, South Asia (SA), South East Asia (SEA) and Latin America (LA), are also analysed. | C95: FALSE
A96: 553b773cde3b284c8c8e09b84d3bbbbf | B96: In coastal areas, the challenge often exists of preventing the destruction of sand dunes owing to the construction of tourism facilities close to the water. The degradation of sand dunes not only alters the coastal ecosystem but, in the long run, also increases those facilities’ exposure to storms and water rise (Magnan, 2014). This situation entails a typical tradeoff between economic development and environmental challenges. Ideally, an integrated approach would attenuate the impact of the trade-off by limiting habitat degradation and consequently the collateral effect on assets in terms of their exposure to climate-related hazards. Such an approach may not completely eliminate the trade-off, but, by taking into account the negative effects, it can put in place compensation mechanisms, such as for protecting marine ecosystems so as to allow them to maintain their natural resilience and adaptive capacities, and then ensuring that their buffering function against waves is maintained (ibid.). | C96: FALSE
A97: 7233af3cdd64e050af652f765a197230 | B97: Ministers reaffirmed their commitment to implement the APEC environmental goods list, which lists goods on which APEC members will reduce tariffs by the end of 2015. In 2014, this included briefings by CITES, the Convention on Biological Diversity (CBD) and the United Nations Framework Convention on Climate Change (UNFCCC). New Zealand briefed the CTE on the jointly organized Parties meeting held in Lima in December 2014. | C97: FALSE
A98: 0d3ace55e7a546da51f0b83614df28ad | B98: Bilateral DFIs are usually owned by donor governments, source their core capital from official development funds, and have access to government guarantees. Some examples include Proparco (France), DEG (Germany) and FMO (Netherlands). The multilateral equivalents of DFIs are the private sector arms or departments of multilateral development banks (such as the International Finance Corporation under the World Bank Group, and non-sovereign operations under the regional development banks). | C98: FALSE
A99: 4cf9ad44865017149316746a9793ad1b | B99: However, when such actions provide both private and public benefits, the public sector may play a role in how these are developed. This report aims to establish a framework to help identify specific actions that governments could take in this respect and that could avoid sending signals leading to non-adaptation or maladaptation. This report begins with a review of national adaptation strategies for the agricultural sector in OECD countries and highlights different approaches undertaken by governments. | C99: FALSE | D99: Adaptation could be about any topic.
A100: 945ccccd978d0ebc2fddd1f5676a1690 | B100: Through the Tonga Education Sector Programme (TESP), for example, Tonga’s Ministry of Education, Women’s Affairs and Culture undertook its first ever approach to sector-wide strategic planning, resulting in a number of substantive changes to approaches and policies. These activities all reinforce the view that ESD is not something that one party subjects another to. Rather, it is a process of ongoing learning and iteration whereby all involved should grow and adapt as a result. | C100: FALSE | D100: Could be true. Education on sustainable development probably involves climate change, but is not specific to it.
A101: b182cb41431ee6bc0c3db7410462928b | B101: Teachers may learn about ESD and related topics, and may be highly motivated during training activities, but upon returning to their classrooms they struggle to find the time or means to effectively implement what was learned. This is disheartening and inefficient. As attractive as training activities may be to donors as a means of targeting large numbers, and as a means of disseminating ESD knowledge and skills, the surrounding context of such training and the anticipated classroom implementation need to be given serious consideration. In the SEP approach, training is not conceived of as a one-off event expected to change teaching practices on its own, but rather as a component of a broader system of supports and incentives which exerts a positive force on teaching practices over time. | C101: FALSE | D101: Could be true. Education on sustainable development probably involves climate change, but is not specific to it.

Sheet Jean-Baptiste
A1: Text ID | B1: Text | C1: SDG 13 Label | D1: Comments (optional)
A2: 2ce23ba1ca724800a7753d7728b03791 | B2: The discussion covers a variety of international and national actors, including development finance institutions, international climate funds, governments and relevant government agencies. Data regarding global finance flows are mostly drawn from the Climate Policy Initiative (CPI) reports as they represent the most comprehensive source of such flows to date. Second, the paper focuses on the regional landscape of climate finance in the Asia-Pacific region, with particular attention given to active climate funds, multilateral development banks, the distribution of climate finance across countries, and national-level initiatives. | C2: TO DO
A3: 701b01382264358af6eecebbabe5d716 | B3: Authorship is usually collective, but principal authors are named. Some programmes have multiple donors, in which case they have been recorded under the agency that supplied the document. Some projects and programmes only have ex ante evaluations, others have ex ante and ex post evaluations as well as a number of intermediate reviews. This is in part due to the timing of the projects. | C3: TO DO
A4: 3dfa766f6f36763d498549844dd47646 | B4: This was agreed to by more than 130 countries and lays out agreed principles for effective development finance that also cover climate-related aid: these principles relate to country ownership, alignment, harmonisation, results and mutual accountability. The subsequent Busan Partnership on Effective Development Co-operation (2011), agreed to by 150 countries, outlines the importance of climate finance as well as extending the scope of these principles beyond aid to cover development finance and development co-operation more broadly. These include both general principles as well as those developed in the context of funds established by the UNFCCC process such as the Green Climate Fund and the Global Environment Facility. | C4: TO DO
A5: 9fd2870b7e589b645d6740ac4d498527 | B5: This indication came at COP16 in Cancun, when a senior member of the Chinese delegation declared that there had been some rethinking on transparency: "Now we think: if we have done something, why not say so?"121 Having formerly refused international monitoring of domestic mitigation efforts, this statement suggests a loosening of a tightly held position. While the implementation schemes have not yet been agreed, this development does signal a change. On the one hand, as the Copenhagen pledge has been incorporated into the twelfth five-year programme, the central leadership feels reassured that China will meet its target and thus not risk being exposed as a weak and unreliable actor in the international regime. | C5: TO DO
A6: 3304000bcbe473a0c98686d217438277 | B6: Country ownership is a principle of the Busan Partnership for Effective Development Cooperation building on the Paris Declaration and the Accra Agenda for Action. While the past 15 years have tended to separate development finance to achieve the MDGs from climate finance to achieve the goals of the UNFCCC, Agenda 2030 and the Paris Agreement place climate action into the context of sustainable development. In addition, the emphasis in all the 2015 outcomes on country ownership provides an opportunity to increase coherence at national level, especially if partner countries are supported to strengthen human and institutional capacity. | C6: TO DO
A7: f06040907eee4b7aa1263f154e417276 | B7: These indicators are likely to have a micro-coverage in terms of geographical exposure (e.g. few communities) and life spans (few years), and to be specific to the programme in question. The data needed to implement this approach are project data and information (often gathered via project-specific surveys). The research concludes that monitoring and evaluation frameworks should combine qualitative, quantitative and binary indicators. | C7: TO DO
