Workbook

Sheet Info
B2: Hello 👋
B4: Welcome to the labeling exercise for SDG 7.
B5: The objective of this exercise is to label 100 texts in terms of their relevance to SDG 7.
B7: Your Labeling Sheet
B8: You have your own personal sheet for assigning the labels. You will find it by clicking on your name in the list at the bottom of this page.
B9: Each sheet has the same 100 texts, but the order in which they appear has been randomized.
B10: Later on, we will put everyone's labels side-by-side. This will help us identify texts with high and low alignment.
B11: At our next meeting, we will discuss the texts where we have disagreements and see if we can reach a consensus for the "true" label for every text.
B12: Please resist the temptation to look at other people's labels until you are done labeling. 🙂
B14: Explanation of Labels
B15: On your personal sheet, you will find the text in column C.
B16: Column D contains a drop-down for picking the appropriate label. The options are:
B18: SDG 7 | C18: This text is relevant to SDG 7
B19: NOT SDG 7 | C19: This text is not relevant to SDG 7
B20: SKIP | C20: You can use this if you are not sure about the label
B22: If you want, you can put any comments in column E.
B24: Instructions for Labeling
B25: The text should be annotated as SDG 7 only if:
B27: 1. The text addresses SDG 7 or one of its targets
B28: See the official definitions of SDG 7 and its targets below ("SDG 7 Description & Targets").
B30: AND
B32: 2. The text addresses SDG 7 or its targets directly:
B33: - the text should be directly relevant to SDG 7 or to achieving SDG 7
B34: - if a text only has an indirect relevance, it should not be labeled SDG 7
B35: Example: "We are subsidizing the costs of silicon" does not qualify for SDG 7, even though silicon is one of the materials for making photovoltaic cells and reduced cost of silicon might have indirect benefits for the expansion of solar energy.
B37: AND
B39: 3. The text addresses SDG 7 or its targets specifically:
... B68: Please click on your name to access your personal labeling sheet. Names are listed in alphabetical order.
B70: Name | C70: Progress (will update automatically)
B71: Dina | C71: =IFERROR(__xludf.DUMMYFUNCTION("SPARKLINE((100-COUNTIF(INDIRECT(B71&""!D:D""), ""TO DO""))/100+0.01,{""charttype"",""bar"";""max"",1.01;""min"",0; ""color1"", ""#4285f4""})"),"") | D71: =(100-COUNTIF(INDIRECT(B71&"!D:D"), "TO DO")) & " / 100" -> 0 / 100
B72: Finn | C72: =IFERROR(__xludf.DUMMYFUNCTION("SPARKLINE((100-COUNTIF(INDIRECT(B72&""!D:D""), ""TO DO""))/100+0.01,{""charttype"",""bar"";""max"",1.01;""min"",0; ""color1"", ""#4285f4""})"),"") | D72: =(100-COUNTIF(INDIRECT(B72&"!D:D"), "TO DO")) & " / 100" -> 100 / 100
B73: Gib | C73: =IFERROR(__xludf.DUMMYFUNCTION("SPARKLINE((100-COUNTIF(INDIRECT(B73&""!D:D""), ""TO DO""))/100+0.01,{""charttype"",""bar"";""max"",1.01;""min"",0; ""color1"", ""#4285f4""})"),"") | D73: =(100-COUNTIF(INDIRECT(B73&"!D:D"), "TO DO")) & " / 100" -> 11 / 100
B74: Jean-Baptiste | C74: =IFERROR(__xludf.DUMMYFUNCTION("SPARKLINE((100-COUNTIF(INDIRECT(B74&""!D:D""), ""TO DO""))/100+0.01,{""charttype"",""bar"";""max"",1.01;""min"",0; ""color1"", ""#4285f4""})"),"") | D74: =(100-COUNTIF(INDIRECT(B74&"!D:D"), "TO DO")) & " / 100" -> 100 / 100
B75: Meike | C75: =IFERROR(__xludf.DUMMYFUNCTION("SPARKLINE((100-COUNTIF(INDIRECT(B75&""!D:D""), ""TO DO""))/100+0.01,{""charttype"",""bar"";""max"",1.01;""min"",0; ""color1"", ""#4285f4""})"),"") | D75: =(100-COUNTIF(INDIRECT(B75&"!D:D"), "TO DO")) & " / 100" -> 0 / 100
B76: Steve | C76: =IFERROR(__xludf.DUMMYFUNCTION("SPARKLINE((100-COUNTIF(INDIRECT(B76&""!D:D""), ""TO DO""))/100+0.01,{""charttype"",""bar"";""max"",1.01;""min"",0; ""color1"", ""#4285f4""})"),"") | D76: =(100-COUNTIF(INDIRECT(B76&"!D:D"), "TO DO")) & " / 100" -> 100 / 100
B78: Thank you for being part of this exercise and thanks to OSDG for the dataset! ❤️

Sheet Coding Manual
A1: Construct definition
A2: Goal 7. Ensure access to affordable, reliable, sustainable and modern energy for all
A3: 7.1 By 2030, ensure universal access to affordable, reliable and modern energy services
A4: 7.2 By 2030, increase substantially the share of renewable energy in the global energy mix
A5: 7.3 By 2030, double the global rate of improvement in energy efficiency
A6: 7.a By 2030, enhance international cooperation to facilitate access to clean energy research and technology, including renewable energy, energy efficiency and advanced and cleaner fossil-fuel technology, and promote investment in energy infrastructure and clean energy technology
A7: 7.b By 2030, expand infrastructure and upgrade technology for supplying modern and sustainable energy services for all in developing countries, in particular least developed countries, small island developing States, and land-locked developing countries, in accordance with their respective programmes of support
A9: Rules of annotation
A10: The text should be annotated as SDG 7 only if:
A11: 1. The content addresses SDG 7 or one of its targets
A12: - affordable/ reliable/ sustainable/ modern energy
A13: - the (access to) this energy
... A40: - transportation: when about transportation in energy-efficient way, should be SDG 11

Sheet Dina
A1: DOI | B1: Text ID | C1: Text | D1: Label | E1: Comments (optional)
A2: 10.1787/5kg20639kgkj-en | B2: 90e3f33798e2cfc95c140ef186fb00a9 | C2: Sustainability Advantage is a business support service from the Department of Environment and Climate Change NSW. It is designed to help organisations understand sustainability, successfully manage for a better environment and add business value79. Industry' Investment NSW offers “LEAN and green” business master classes for people who want to leam how they can improve business efficiency through the application of “lean” business practices, coupled with environmental sustainability, to reduce costs, increase profits, open new markets and create jobs . Despite initiatives like these, it is not always easy for SMEs to take up training opportunities in skills for sustainability. | D2: TO DO
A3: 10.1787/9789264303119-en | B3: 3b67ed2c408fb9348a08325fa98f3dbe | C3: Furthermore, the most severe accidents have occurred in these stages. Most of the severe accidents involved tankers (collisions, explosions, fires and impact with the ground) and road accidents during regional distribution. In the oil chain, fatalities are fairly evenly distributed among workers and the public (Burgherr and Hirschberg, 2008a). | D3: TO DO
A4: 10.18356/fcd1ba6c-en | B4: 2528f76d29c8a44be2769f22b552e9a8 | C4: Scepticism about the science is no longer an option: the world’s scientists have never been so unanimous, and so ominous, in their projections of future perils. The bad news is that too many participants in the debate consider a climate policy as consisting primarily of manipulating markets and prices. If the only tool available were market liberalization, then the solution to every problem would seem to be a matter of getting the prices right. But setting a price for carbon emissions is only the beginning of climate policy - not the end. | D4: TO DO
A5: 10.18356/7e830810-en | B5: 0edfe3b90c82ce644cf8c58342f13172 | C5: Where energy supply is unreliable, firms are more concerned with availability than with efficiency. Similarly, small and medium-size industrial firms find it much harder to get a loan than do larger firms. And while the barriers to energy efficiency are also present in developed countries, they are more formidable in developing countries. What are the appropriate roles of the public and private sectors? | D5: TO DO
A6: 10.1787/5k9312v21l6f-en | B6: 60a148ee953bd6d9349f85d897641289 | C6: These initiatives need to be encouraged, carefully monitored, and expanded where successful. Fiona Stewart is a principal administrator in the Financial Affairs Division of the OECD’s Directorate for Financial and Enterprise Affairs. The views expressed are the sole responsibility of the authors and do not reflect those of their organisations or the governments of OECD Member countries. The authors are solely responsible for any errors. | D6: TO DO
A7: 10.14217/9781848599574-13-en | B7: 1982e8b824ff8e01f7ec3ac363f26441 | C7: Electricity grids in the Pacific will need to be strongly interconnected, flexible enough to accommodate this change, and resilient enough to withstand climate impacts, as well as cope with potential demand growth from growing populations and growing electric vehicle use. Commonwealth Pacific small states are more dependent on the fossil fuels used in cars, trucks and boats than for generating electricity, and more cost-effective displacement of fossil fuel can occur through energy efficiency. However, the attention and funding of development partners is not always directed accordingly to these areas. Moreover, although this is improving, consumers generally lack awareness on how they can reduce their energy consumption or be more energy efficient. The International Renewable Energy Agency (IRENA) estimates that deploying renewables worldwide on the scale necessary to limit global temperature rise below 2 degrees would require current investment to double by 2020, and triple by 2030 to around US$900 billion annually (IRENA 2016b). | D7: TO DO
A8: 10.1787/9789264188617-en | B8: 6c094b959f7578c34063732cedc4a7ae | C8: The OECD is also at the forefront of efforts to understand and to help governments respond to new developments and concerns, such as corporate governance, the information economy and the challenges of an ageing population. The Organisation provides a setting where governments can compare policy experiences, seek answers to common problems, identify good practice and work to co-ordinate domestic and international policies. The European Commission takes part in the work of the OECD. Current NEA membership consists of 30 OECD member countries: Australia, Austria, Belgium, Canada, the Czech Republic, Denmark, Finland, France, Germany, Greece, Hungary, Iceland, Ireland, Italy, Japan, Luxembourg, Mexico, the Netherlands, Norway, Poland, Portugal, the Republic of Korea, the Slovak Republic, Slovenia, Spain, Sweden, Switzerland, Turkey, the United Kingdom and the United States. The European Commission also takes part in the work of the Agency. | D8: TO DO
A9: 10.1787/5kmh3nj5rzs4-en | B9: be8a2af1834e66add5d63d32dcf2761e | C9: This debate is in line with South Africa's rural electrification agenda, as new power generation will be necessary to service more households. The average official50 unemployment figures are above 20% (see Table 33), excluding the under-employed in the rural and urban areas or those who are not registered in employment agencies. Payment for electricity is an issue for people who have no or very little income. Many cases of domestic violence in newly electrified households have been amply documented. It is argued that domestic trouble starts over priorities when resources are scarce (Habitat for Humanity, 2009). However, the long-term effect of ensuring universal access to electricity should lead to general opportunities for a broad-based economic development. | D9: TO DO
A10: 10.6027/9789289330954-4-en | B10: 138cf928dfb2490a23508d1175375c10 | C10: The country's potential in developing energy production technologies like wave power and osmotic power is also substantial. Norway is Europe's largest producer of hydropower, which delivers 99% of the country's electricity. On January 1 2008, Norway had a total installed capacity of 29030 MW at 699 hydropower stations larger than 1 MW. The Kvill-dal hydropower station in Rogaland county is Norway’s largest, with a maximum generating capacity of 1240 MW. | D10: TO DO
A11: 10.18356/a81ec314-en | B11: ddd9ab387d2fc7238a7336e01f4480c3 | C11: These new partnerships arc working to provide the most cost-cfTcctivc electrification solutions, especially in remote communities that arc often the most disadvantaged in terms of electricity access. Though progress in electrification continued at the regional level, it slowed in the recent period, attributable to population growth in rural areas and the ongoing difficulty of extending services to remote areas. The rate of progress has declined in countries with the largest deficits, namely India, Bangladesh, and Myanmar, while the lowest access rates arc found among a number of Pacific Island and least developed State.4 Though urban areas in most economics have achieved universal access, rural areas lag behind, and, in a few cases with growing rural populations, rural electrification rates are falling. | D11: TO DO
A12: 10.1787/9789264180444-17-en | B12: 0d02b195616490f828e9c7e99e293799 | C12: The University of Troms0 has over 9 000 students and some 2 500 employees. Since Troms County has only 1% of its surface area classed as cultivable land, agriculture is a relatively minor part of land use. It is mainly located around the coast and was traditionally combined with fishing to form a key part of rural livelihoods. Troms County is at the northern limits of agricultural production possibilities, but the Gulf Stream enables some seasonal farming around the coasts and fjords, while the Sami people also carry out traditional reindeer herding. | D12: TO DO
A13: 10.1787/5kmh3nj5rzs4-en | B13: 09d371f072d386c66ae086329a44aa38 | C13: In 2008, 70.8% of India's total population lived in rural areas, progressively migrating to urban areas at an annual rate of 2.3%, a rate which is below that of many other countries (UNPD, 2008). While such economic development has led to an average increase in the standards of living, it has left the agricultural sector untouched, bypassing most of the rural poor. Therefore, although India has enjoyed a growth of GDP per capita, poverty remains a challenge. Poverty is also more concentrated in some states such as the eastern and north-eastern states as Figure 7 shows. In March 2007, the Indian Planning Commission estimated that over the 2004-2005 Page | 63 period, more than one-quarter of India's total population (27.5%) still lived below the poverty line (BPL), with a distribution of 25.7% urban dwellers and 28.3% rural dwellers (Planning Commission, Government of India, 2007)37 as seen in Table 17. But strong economic growth alone does not bring such amenities to the rural poor. | D13: TO DO
... A101: 10.6027/9789289329163-8-en | B101: f8a730809d29ac515eb7c5e34389c1b6 | C101: Consequently, there are more business options for the forest industry and forest-based raw materials than ever before. It still needs to be remembered that all four levels must be able to co-exist also in the future, even if their shares may change. All that can be produced without felling trees, e.g. carbon sinks, berries, game, tourism, etc. | D101: TO DO

Sheet Finn
A1: DOI | B1: Text ID | C1: Text | D1: Label | E1: Comments (optional)
A2: 10.1787/5kg20639kgkj-en | B2: 448cfebe196e9aed00270dbd6ed9d3ce | C2: Not only does this have potentially negative effects on gender pay gaps and levels of social inclusion, but also Sydney is not fully utilising the skills currently available in its workforce. Moreover, this mixed labour market picture suggests that the low levels of unemployment are masking higher levels of inactivity. Youth unemployment is also high, although this is very much a global trend amongst advanced economies. | D2: NOT SDG 7
A3: 10.1787/5bbcdeac-en | B3: 6194ce1da1e7aed5cd5e9929d75f9742 | C3: An enabling policy environment is important for the development of a strong and competitive renewable energy sector to supply both industrial and domestic consumers. Section 3 identifies key enabling policy factors required for the replicability and accelerated uptake of the available renewable energy solutions throughout the mining sector. Major companies and conglomerates, among others, such as Glencore, Barrick Gold, Rio Tinto, Antofagasta, Codelco and IAMGOLD have all made use of renewable energy in their mines (Table 2.1). | D3: SDG 7
A4: 10.1787/9789264303119-en | B4: 881afd0ec024eaac99cb05f2a12897f2 | C4: If the latter are already difficult to determine for marketed goods, the intrinsic complexity of external costs prevents the establishment of social welfare functions adopting a broader notion of welfare. To a large extent social costs are external, i.e. not internalised, precisely because no well-defined utility functions exist. Discussion quickly shows that any framework based solely on static optimisation will run into internal contradictions. | D4: NOT SDG 7
A5: 10.6027/9789289349918-3-en | B5: 725de70f6686eefb96c1653b790d6b6a | C5: A way to improve energy efficiency is to tap the huge potential for efficiency gains in the building sector which is the largest single energy consumer in Europe, absorbing 40% of final energy. About 75% of buildings are energy inefficient and, depending on the Member State, only o.4-1.2% of the stock is renovated each year. ( The energy efficiency target on EU level is set on fixed Mtoe-level for final energy and primary energy use in 2030, and the Member States have to set their targets so that this target will be reached. The Commission will lay down a process to ensure that the contributions add up to the Union's 2030 energy efficiency target in the legislative proposal on Energy Union Governance. | D5: SDG 7
A6: 10.18356/1e8b62ff-en | B6: 4cb4009dc0f591e05e2f3e8e69a32234 | C6: By 2014, more than 1,000 microhydro systems had been installed, with total generating capacity of 22 MW, providing off-grid electricity access to 20 per cent of the population. Credible long-term policy commitment, with flexible approach to implementation and reduced administrative burdens, is essential to sustaining mini-grid deployment. In this respect, the availability of a potential anchor load — i.e., a consumer of a large and possibly stable proportion of the power generated (for instance a small factory, hospital or farmer cooperative) — supplementing households’ electricity demand is usually critical to support mini-grid profitability and increase capacity utilization. | D6: SDG 7
A7: 10.1787/5kmh3nj5rzs4-en | B7: 09d371f072d386c66ae086329a44aa38 | C7: In 2008, 70.8% of India's total population lived in rural areas, progressively migrating to urban areas at an annual rate of 2.3%, a rate which is below that of many other countries (UNPD, 2008). While such economic development has led to an average increase in the standards of living, it has left the agricultural sector untouched, bypassing most of the rural poor. Therefore, although India has enjoyed a growth of GDP per capita, poverty remains a challenge. Poverty is also more concentrated in some states such as the eastern and north-eastern states as Figure 7 shows. In March 2007, the Indian Planning Commission estimated that over the 2004-2005 Page | 63 period, more than one-quarter of India's total population (27.5%) still lived below the poverty line (BPL), with a distribution of 25.7% urban dwellers and 28.3% rural dwellers (Planning Commission, Government of India, 2007)37 as seen in Table 17. But strong economic growth alone does not bring such amenities to the rural poor. | D7: NOT SDG 7
A8: 10.1787/5k3wb8fmsz6h-en | B8: e45e89c440f096f7dedfee2104c05be1 | C8: Looking forward, the development of storage technologies and the development of international interconnections are foreseen to further facilitate the integration of wind and solar power. In these situations, balancing the power system during periods of low load will necessitate further adaptations to maintain the physical parameters of the network. An ongoing IEA work within the Grid Integration of Variable Renewables project (GIVAR) analyses these options in more detail. Hence, it will be necessary in the next 20 years to keep some conventional power plants online to provide ancillary services and ramp-up capabilities. | D8: SDG 7
A9: 10.14217/9781848599574-13-en | B9: 4ab2d07728c9a63879cfc15e268f6aba | C9: The percentage of the population that has access to electricity ranges from 18 per cent in PNG to 100 per cent in Samoa (Figure 9.4). A larger proportion of hydro power, for example in Fiji, is likely to reduce the electricity tariff, whereas a country that relies mostly on fossil fuels, such as Kiribati or Tuvalu, is more vulnerable to increasing oil prices. Another factor affecting the residential electricity tariff is whether it is subsidised through the Government budget, for example in Fiji, or using a cross subsidy from larger users of electricity, for example in Vanuatu. Each power utility in each country determines its tariffs differently. | D9: SDG 7
A10: 10.1787/5k49dv6c5xmv-en | B10: 7b76b91e09d54abc84b480f0db7f37e8 | C10: Low-wage residents are less likely to have access to a car, and commuter train lines and bus routes do not serve the south side of the Tri-State metro-region as well as they serve other parts of the region. Commuting times are even longer for those who commute across the region instead of following the hub and spoke system. Investment in public transport infrastructure does not sufficiently respond to demand for access to jobs, especially in lower -income neighbourhoods. While the Tri-State metro-region ranks high among OECD regions on many technology-based innovation indicators in terms of volume, its position has slipped and it is not among top regions when controlling for the size of its population and economy. For instance, in terms of patents per capita, the Tri-State metro-region ranked 23rd among OECD metro-regions and 11th among US metro-regions in 2007, the last year for which data are available, it ranked 27th and 12th, respectively, when adjusting for GDP (Table 1.5). These are hardly poor scores, but neither do they suggest that the Tri-State metro-region is fulfilling its innovation potential, particularly given that it ranks below so many other US metro-regions, including San Diego, San Francisco, New York, Boston, Los Angeles and Houston. | D10: NOT SDG 7
A11: 10.14217/9781848599574-13-en | B11: 2a678f26ee1012ffd2f13e781a70ad92 | C11: In its recent national plan, the Kiribati Development Plan 2016-19, the government has focused on improving infrastructure for the energy sector, including in renewables. The Kiribati Joint Implementation Plan on Climate Change and Disaster Risk Management notes the vulnerability of women, youth and children. In the past, Nauru’s economy was dependent on the phosphate industry, which also fuelled its energy demand. | D11: SDG 7
A12: 10.1787/9789264303119-en | B12: 07f17e85fc779d9e2b6f72fc7e884546 | C12: There are, however, many other potential impacts of accidents that are borne by the society as a whole and for which the internalisation is less straightforward and more complex. This is the case for the economic consequences on health and on the business property of a third party or on the environment. The entity liable for the accident is held responsible for the victims’ compensation, which ensures a certain internalisation of accident costs. | D12: NOT SDG 7
A13: 10.18356/cefc94d2-en | B13: 03aceee76df8ed0511df92e8262c69c8 | C13: Tracking progress towards achieving the Sustainable Development Goals requires the collection, processing, analysis and dissemination of data and statistics at the subnational, national, and regional levels, including those derived from official statistical systems and from new and innovative data sources. Many national statistical systems face serious challenges in this regard. As a result, accurate and timely information about certain aspects of people's lives are unknown, and many development challenges are still poorly understood. | D13: NOT SDG 7
A14: 10.1787/saeo-2017-8-en | B14: d974c1ee71b4e0f13b3df4e577c038e4 | C14: This corresponded to 32% of the total final energy consumption in the entire region. In parallel, India’s industry will play an increasingly important role as a driver for energy consumption in the region. While India’s industry accounted for 7% of the TFC in emerging Asia in 2013, this share is expected to increase to 13% by 2040. | D14: NOT SDG 7 | E14: This text is clearly about energy — but is specific to the objectives of SDG 7?
A15: 10.1787/5k49dv6c5xmv-en | B15: 7cf11d73e5bb2de5ea82cb92952a4065 | C15: Despite benefiting from past investments that have given it the second-longest commuter rail system in the US, investment has not kept up with the region’s needs. The Chicago Tri-State metro-region's competitiveness is being undermined in part by the growing inadequacy of its transportation infrastructure, which is typified by high rates of road congestion. Over 80% of the 4 009 stream miles assessed in Illinois are considered sufficiently polluted to prohibit primary human contact (e.g. swimming) (IEPA, 2010). | D15: NOT SDG 7
A16: 10.18356/fcd1ba6c-en | B16: e5b9f53cfda6ec1c21ceadb708f69d48 | C16: The world’s leaders call for massive investment in the developing world, and UNEP insists that this investment be in green development. The International Energy Agency estimates that some $44 trillion - over and above the business-as-usual scenario - will be needed by 2050 to meet even the lowest of the IPCC’s estimates for stabilizing global climate, most of it in the developing world. Indeed, the agreements and contracts signed contain clauses that make a sustainable approach to development well-nigh impossible. We call for one thing in our political declarations, but do a very different thing in reality. | D16: NOT SDG 7
A17: 10.1787/9789264188617-en | B17: 5541a26c0b86bbefdc00ed32a2db20ad | C17: Connecting an individual consumer to a power plant would be prohibitively expensive. However, each additional customer in the area reduces the average cost for all involved since the cost for connecting the additional customer is small. The physical link through the grid, however, not only links customers to a producer but also links all producers with each other. | D17: SDG 7
A18: 10.18356/d0196687-en | B18: 46d475ceaa034365791d668459aa60cb | C18: In addition to targets, the scope of instruments related to renewable energy being introduced is also broadening, demonstrating a deepening commitment towards renewable energy. For instance, Sri Lanka, under its latest energy sector development plan, is seeking to significantly increase the share of renewable energy while reducing petroleum imports, which have risen dramatically over the past decades (Sri Lanka, Ministry of Power and Renewable Energy, 2015). Pacific Island States, particularly the Cook Islands, Fiji, Samoa, Tuvalu, and Vanuatu, are leading the region in setting up an ambitious target of 100 per cent renewable energy. Additionally, under the country’s Energy Development Strategic Action Plan, hydro is expected to reach approximately 350 GW. | D18: SDG 7
A19: 10.1787/5k3wb8h0dg7h-en | B19: 08f9f7626f2c2baf6922a89d1b569335 | C19: Since 2007 Italy has provided tax relief for energy efficiency improvements to existing buildings including the installation of double-glazed windows, thermal insulation, high-efficiency boilers and the installation of solar panels. In 2009, building owners submitted 240,000 tax credit applications. As the programme was originally expected to be terminated in 2010, the number of applications in 2010 exceeded the previous year by around 71%. | D19: SDG 7
A20: 10.18356/893fb414-en | B20: 0c0f79ed4ec9a79fca8cc8392ba2c73f | C20: Energy poverty both signifies and drives overall poverty. More than 95% of the world population without electricity lives in Sub-Saharan Africa and developing Asia. In Sub-Saharan Africa, two-thirds of the population (620 million people) does not have access to electricity (IEA 2015a). Lack of electricity is generally most prevalent in rural areas. | D20: SDG 7
A21: 10.1787/5kg51nfc1321-en | B21: baebc2406cec83bb365787cbd8c18104 | C21: This option could lead to achieving the goal of a 40% reduction in energy intensity by 2030. The largest impact in energy intensity reduction will stem from efficiency improvements in the industrial and residential sectors. These products must be rapidly distributed on a large scale to achieve energy savings and reduce worldwide emissions. | D21: SDG 7
A22: 10.1787/5kgglrw4n7s0-en | B22: 29d5da40fe85cc32f02d021b960ce2f8 | C22: Large areas of about 500 000 km2 between Mumbai and Bhopal and in Gujarat are covered by thick basalt layers. If basalt is shown to be a suitable cap rock, it is estimated that this would allow storage of 300 Gt C02 (Sonde, 2007). Three of the nine sites designated so far for UMPP projects are on the coast not far from these potential storage areas.13 For inland sites relying on domestic coal, additional costs of USD 5/tC02 for transporting the C02 are expected compared to coastal sites (Mott MacDonald, 2008). Gas consumption has been rapidly growing at a rate of 8% between 1990 and 2009. | D22: NOT SDG 7
A23: 11.1002/pub/807e55db-ec047466-en | B23: 0e70884074d0aaff7bcc68c77c674a8b | C23: According to the battery specification, the voltage is 3.3 V and capacity is 0.8 Ah, which implies Cphone = 2.96 [12]. The final parameter is calculated as F = 0.375, derived from the average monthly charging expenses of $2.25 and the average price per charge of $0.20 [3]. Consequently, Ephone = 24.5. | D23: NOT SDG 7
A24: 10.18356/a81ec314-en | B24: ddd9ab387d2fc7238a7336e01f4480c3 | C24: These new partnerships arc working to provide the most cost-cfTcctivc electrification solutions, especially in remote communities that arc often the most disadvantaged in terms of electricity access. Though progress in electrification continued at the regional level, it slowed in the recent period, attributable to population growth in rural areas and the ongoing difficulty of extending services to remote areas. The rate of progress has declined in countries with the largest deficits, namely India, Bangladesh, and Myanmar, while the lowest access rates arc found among a number of Pacific Island and least developed State.4 Though urban areas in most economics have achieved universal access, rural areas lag behind, and, in a few cases with growing rural populations, rural electrification rates are falling. | D24: SDG 7 | E24: Typos in text
A25: 10.6027/9789289330954-4-en | B25: 138cf928dfb2490a23508d1175375c10 | C25: The country's potential in developing energy production technologies like wave power and osmotic power is also substantial. Norway is Europe's largest producer of hydropower, which delivers 99% of the country's electricity. On January 1 2008, Norway had a total installed capacity of 29030 MW at 699 hydropower stations larger than 1 MW. The Kvill-dal hydropower station in Rogaland county is Norway’s largest, with a maximum generating capacity of 1240 MW. | D25: SDG 7
A26: 10.6027/8a4204a0-en | B26: 3de3a33b6c50a93b9bf0e13ad8c0d089 | C26: Throughout this week, electricity prices are relatively high, with a clear day-night pattern. Night prices of around 50 EUR/MWh are close to the marginal cost of coal fired power plants, while the higher prices during day times of around 90-100 EUR/MWh are close to the marginal cost of natural gas fired power plants. Total consumption (red dashed line), however, is more constant over the week, because electricity consumption for heating and pumping (pumped storage) increases at night, when electricity prices are low. | D26: SDG 7
A27: 10.1787/5k49dv6c5xmv-en | B27: 23f59c31e9d0ddbb55a5f4b2df177abb | C27: Although its ranking in terms of GDP per capita among OECD metro-regions is not as high as it is in terms of GDP (16lh among the 90 metro-regions vs. 8lh), Chicago still counts among the big players in the OECD urban world. With GDP per capita over USD 55 000 in 2008, Chicago ranked higher than traditionally rich European metro-regions such as London, Stockholm, Helsinki, Amsterdam-Utrecht, Paris and Milan (Figure 1.2). Among US metro-regions, Chicago’s GDP per capita is similar to that of San Diego and Philadelphia, but below that of a number of US metro-regions such as New York, Los Angeles, San Francisco-Oakland, Boston or Houston. | D27: NOT SDG 7
A28: 10.18356/04b2e7d9-en | B28: 02bac9d17475999b1e8cd569255dca67 | C28: Strategies include building national and regional institutional capacity, cost sharing across borders, governance and regulations, enhancing access to modern energy, developing low-carbon and renewable domestic resources, improving regional energy cooperation and energy security, and promoting private sector participation in energy development. One key focus area is the development of hydropower potential, especially in the Lao People's Democratic Republic. Other activities pertaining to the energy sector include issues related to development of new and renewable sources (including small hydro), addressing the food-energy nexus, standardization and testing. These are captured in the BIMSTEC Memorandum of Understanding on Grid Interconnection. | D28: SDG 7
A29: 10.18356/73c3a080-en | B29: 62d5095d5d7ac925505de89dc9f446e1 | C29: Electricity access is commonly acknowledged as a basic need for human development (Scott and Seth, 2013), and has been described as a moral imperative, socially prudent and an economic necessity (GEA, 2016: 19). Aside from the public-good dimension of safe and reliable electricity supply, consumer protection and guaranteed access are important political-economy considerations (Bamber et al., Such energy-security concerns generally serve to reinforce State control and regulation of the electricity sector (Kuik et al., | D29: SDG 7
A30: 11.1002/pub/80f4cf5d-443a6582-en | B30: 96e05c536ae4c2f5e574d841bb9a5d41 | C30: The IAEA uses ICTs to support Member States in improving the functionality, safety and security of existing and new Nuclear Power Plants (NPPs) to ensure Affordable and Clean Energy (SDG 7) and improve Industry, Innovation and Infrastructure (SDG 9) by managing complex nuclear lifecycle technology systems. However, the applications of nuclear techniques - and the IAEA's work -in fact extend far beyond just nuclear energy. The IAEA's work extends into the education and training of health professionals in nuclear medicine techniques (SDGs 3 and 4 on health and education, respectively), monitoring of marine contaminants (SDG 14). | D30: SDG 7
A31: 10.1787/5kmh3nj5rzs4-en | B31: 04922124925495a57473febc0637998d | C31: Electrification of schools, however, is facing problems largely stemming from lack of information about the number of schools and their electrification status. Some municipalities fail to report the number of schools in their area or fail to provide accurate information on whether the schools are electrified or not. It is clear that this poses a major constraint for the entities in charge of the electrification of the as-yet un-electrified schools. | D31: SDG 7
A32: 10.1787/9789264236813-6-en | B32: 4cf9ebc3e44f6f6fe764d85a6f3abc99 | C32: In the short-term, a favourable future for the post-2015 sustainable development framework and an ambitious climate deal in Paris will not be possible without policy input. In the longer term, development objectives, including climate-related goals, need policy coherence as well as cash. Governments will need to adapt accordingly. | D32: NOT SDG 7
A33: 10.1787/5kgglrw4n7s0-en | B33: 0bc3671b295153b56be5727afdf182de | C33: On the production side (industry, commerce and agriculture), significant changes are expected as the economy grows nearly eightfold. This implies a massive expansion of the commercial/services sector (by a factor of six), a significant expansion of manufacturing activity, and more limited growth of activity in agriculture. However, water needs to be pumped from increasing depth and this is the main source of electricity demand in agriculture. Sources: IEA, 2009b, IEA, 2010a, IEA, 2009c. | D33: NOT SDG 7
A34: 10.18356/e9fa9dd4-en | B34: b9444ad7737b7622d6c248eff6b124ee | C34: Building an attractive rurality for young people is a major public policy challenge. Restoring the attractiveness of rural areas and achieving a new inclusive and equitable rurality is fundamental for rural territories to benefit from having more and better educated young people with a greater capacity for innovation. Thus, the rural agenda increasingly overlaps with the indigenous agenda, which includes an integral vision of that world, as territory and habitat, and not only as a space and production resource. Nonetheless, public must also be formulated for rural Afrodescendent populations, which are significant in various countries and constitute one of the least visible social groups. | D34: NOT SDG 7
A35: 10.1787/9789264096356-en | B35: bbae2a4b69f76f38ff7f5668b95ed44e | C35: Prices that are too low or too volatile discourage investment. Volatile prices also discourage consumers, particularly if their demand elasticity is low. It is a challenge to reach optimal investments levels. Liquid markets on the one side and long-term contracts on the other are important factors in providing investors in producer countries with the necessary visibility for investing in adequate capacity for production, storage and transport. | D35: NOT SDG 7
A36: 10.1787/9789264303119-en | B36: f6d5efdef2f9ea14a47527c057a04920 | C36: Compared with other instances of social costs, one may think of tobacco smoking or lead concentration in drinking water, this process has developed reasonably quickly. First, there is public awareness and opinion creation by means of public communication. These may be commercial means of communication, such as television or newspapers, but also non-commercial means of public awareness creation such as demonstrations, sit-ins, public speeches and the like. Again, information is the first step in internalising external costs. This way, the set of choices is transformed into new choices that integrate a higher share of public concerns. | D36: NOT SDG 7
... A56: 10.18356/5b6c49ea-en | B56: cb7bc8e45845a3c9f2ff7666fe2eaddd | C56: While it is correct that, aside from hydro (the potential of which is low but of high quality) and wind (which provides low-quality power), modern renewables continue to be significantly more expensive, economic limits are ultimately a lesser constraint, as they can be overcome with political will and special efForts. In fact, most energy technology debates completely disregard associated socio-political limits. In pluralistic democracies, the “not-in-my-backyard” (NIMBY) attitude is a powerful factor. | D56: SDG 7
A57: 10.18356/9a9b4252-en | B57: ab620f843a27c589f1c827210740acb6 | C57: For example, in Kenya, the paper manufacturer Chandaria Industries experienced savings of 40 per cent in energy, 48 percent in materials and 181 percent in water through involvement in the programme. Primary education is critical for developing a semi-skilled labour force. In low-income countries with large rural sectors, it can be vital for equipping farmers with the basic skills necessary to their being informed on and implementing sustainable agricultural and forestry practices. However, while the significance of achieving universal primary education is highlighted by its inclusion as a Millennium Development Goal, secondary, vocational and tertiary education are just as important in the field of green technology. Secondary education can provide core skills and knowledge needed for countries’ economic growth. Vocational schooling can be particularly useful in building technological competencies, successful vocational education also provides important links between education and industry. | D57: NOT SDG 7 | E57: "savings of 40 per cent in energy" → SDG 7 or not?
A58: 10.6027/9789289330718-10-en | B58: 87e874216f787a9abf3e6bb66f9fb712 | C58: Both systems also heat water, which integrates with the existing systems on campus to heat the buildings and provide hot water on campus. The system not only provides a sustainable energy system for the campus. For northern communities, the bioenergy project shows how future energy supply in areas with access to biomass may provide a sustainable energy supply. | D58: SDG 7
A59: 10.18356/e1196521-en | B59: 1c4e0e93da40bc305d44546ba12ada49 | C59: Additionally, renewable energy depends on variable wind, sun and exogenous conditions that are intermittent and more difficult to schedule than conventional fossil fuels. Given the limited and still developing electricity storage technology' at utility scale, it is economical to integrate intermittent renewables into larger, flexible electricity systems. The fossil fuel-based generation can be backed down when renewables are available, and with an electricity grid system that covers large geographical areas, the available average renewable resources would be easier to schedule. | D59: SDG 7
...

Sheet Gib
A1: DOI | B1: Text ID | C1: Text | D1: Label | E1: Comments (optional)
A2: 10.1787/9789264236813-6-en | B2: 4cf9ebc3e44f6f6fe764d85a6f3abc99 | C2: In the short-term, a favourable future for the post-2015 sustainable development framework and an ambitious climate deal in Paris will not be possible without policy input. In the longer term, development objectives, including climate-related goals, need policy coherence as well as cash. Governments will need to adapt accordingly. | D2: NOT SDG 7
A3: 10.18356/95417570-en | B3: 0856c7a172a9fe91126e6e9d82492c9b | C3: Sources of energy like geothermal, tidal power, hydrogen, nuclear fusion and so forth will require a more visionary approach and even greater scientific and technological advancement. These advances, in turn, will require substantial investment which, at present, is not forthcoming from public and private sources on a large enough scale. Only by ensuring a reliable, affordable supply of energy will it be possible to chart a stable course for economic recovery and growth. Addressing energy insecurity and transforming the global energy system must therefore constitute a major priority for any long-term programme of economic and climate stabilization in advanced countries. Such a course will simultaneously address the climate challenge. | D3: SDG 7
A4: 10.1787/5kg20639kgkj-en | B4: 448cfebe196e9aed00270dbd6ed9d3ce | C4: Not only does this have potentially negative effects on gender pay gaps and levels of social inclusion, but also Sydney is not fully utilising the skills currently available in its workforce. Moreover, this mixed labour market picture suggests that the low levels of unemployment are masking higher levels of inactivity. Youth unemployment is also high, although this is very much a global trend amongst advanced economies. | D4: NOT SDG 7
A5: 11.1002/pub/80f4cf5d-443a6582-en | B5: 96e05c536ae4c2f5e574d841bb9a5d41 | C5: The IAEA uses ICTs to support Member States in improving the functionality, safety and security of existing and new Nuclear Power Plants (NPPs) to ensure Affordable and Clean Energy (SDG 7) and improve Industry, Innovation and Infrastructure (SDG 9) by managing complex nuclear lifecycle technology systems. However, the applications of nuclear techniques - and the IAEA's work -in fact extend far beyond just nuclear energy. The IAEA's work extends into the education and training of health professionals in nuclear medicine techniques (SDGs 3 and 4 on health and education, respectively), monitoring of marine contaminants (SDG 14). | D5: SDG 7
A6: 10.14217/9781848599574-13-en | B6: 2a678f26ee1012ffd2f13e781a70ad92 | C6: In its recent national plan, the Kiribati Development Plan 2016-19, the government has focused on improving infrastructure for the energy sector, including in renewables. The Kiribati Joint Implementation Plan on Climate Change and Disaster Risk Management notes the vulnerability of women, youth and children. In the past, Nauru’s economy was dependent on the phosphate industry, which also fuelled its energy demand. | D6: SDG 7
A7: 10.18356/fcd1ba6c-en | B7: e5b9f53cfda6ec1c21ceadb708f69d48 | C7: The world’s leaders call for massive investment in the developing world, and UNEP insists that this investment be in green development. The International Energy Agency estimates that some $44 trillion - over and above the business-as-usual scenario - will be needed by 2050 to meet even the lowest of the IPCC’s estimates for stabilizing global climate, most of it in the developing world. Indeed, the agreements and contracts signed contain clauses that make a sustainable approach to development well-nigh impossible. We call for one thing in our political declarations, but do a very different thing in reality. | D7: NOT SDG 7
A8: 10.1787/5kgglrw4n7s0-en | B8: 0bc3671b295153b56be5727afdf182de | C8: On the production side (industry, commerce and agriculture), significant changes are expected as the economy grows nearly eightfold. This implies a massive expansion of the commercial/services sector (by a factor of six), a significant expansion of manufacturing activity, and more limited growth of activity in agriculture. However, water needs to be pumped from increasing depth and this is the main source of electricity demand in agriculture. Sources: IEA, 2009b, IEA, 2010a, IEA, 2009c. | D8: NOT SDG 7
A9: 10.1787/5bbcdeac-en | B9: 6194ce1da1e7aed5cd5e9929d75f9742 | C9: An enabling policy environment is important for the development of a strong and competitive renewable energy sector to supply both industrial and domestic consumers. Section 3 identifies key enabling policy factors required for the replicability and accelerated uptake of the available renewable energy solutions throughout the mining sector. Major companies and conglomerates, among others, such as Glencore, Barrick Gold, Rio Tinto, Antofagasta, Codelco and IAMGOLD have all made use of renewable energy in their mines (Table 2.1). | D9: SDG 7
A10: 10.1787/5k49dv6c5xmv-en | B10: eb2688a4a4cc3e62cf272196046f4f3e | C10: Green job growth over the next 5-10 years is expected to be highest in the building and transportation sectors. Higher energy consumption, rising greenhouse gas emissions, road congestion and deteriorating water quality are the negative externalities that have come with urban growth. Many metropolitan regions across the OECD have turned their attention to the concept of green growth as a means of increasing economic competitiveness through addressing environmental challenges (Box 1.1). What do we mean by urban green growth? | D10: NOT SDG 7
A11: 10.18356/e9fa9dd4-en | B11: b5fdc51af03856168f0dd458f1c47547 | C11: The proportion of the region's population living in slums fell from 34% in 1990 to 21% in 2014 (see figure V.19). In terms of absolute numbers however, although 2 million people left the slums, over 100 million still live in such settlements. This is exemplified by the negotiation of the New Urban Agenda, adopted at the United Nations Conference on Housing and Sustainable Urban Development (Habitat III), held in 2016. | D11: NOT SDG 7
A12: 10.1787/9789264236813-6-en | B12: a5c19681ebb07ae9341468a13396d831 | C12: In 2012,63% of trips during morning and evening peak times were on public transport, compared to 59% in 2008. To increase this number even further, the LTA aims to make the transport system even more accessible and competitive. By 2030, 80% of households should be within a 10-minute walk of a train station, 85% of public transport journeys (less than 20km) will be completed within 60 minutes and 75% of all journeys in peak hours will be via public transport. | D12: NOT SDG 7
A13: 10.1787/5kg51nfc1321-en | B13: baebc2406cec83bb365787cbd8c18104 | C13: This option could lead to achieving the goal of a 40% reduction in energy intensity by 2030. The largest impact in energy intensity reduction will stem from efficiency improvements in the industrial and residential sectors. These products must be rapidly distributed on a large scale to achieve energy savings and reduce worldwide emissions. | D13: TO DO
... A101: 10.18356/7e830810-en | B101: 0934a08badd098559da1fff3aedb86a0 | C101: Some firms might be more sensitive to some types of barriers than to others. One is commonly known as the rebound effect. An example is the driver who replaces a car with a more fuel-efficient model, only to take advantage of its cheaper running costs to drive further and more often. Rebound effects have long been neglected, but their consequences could be profound. | D101: TO DO

Sheet Jean-Baptiste
A1: DOI | B1: Text ID | C1: Text | D1: Label | E1: Comments (optional)
A2: 10.18356/6e8bb756-en | B2: 30c83a848738f5d86d6bd284107e5232 | C2: In the EU, for instance, there was a rapid increase in the market share of the most energy-efficient appliances. Sales of Class A refrigerators increased from less than 5 per cent of total sales in 1995 to 23 per cent in 2000 and 61 per cent in 2005, in addition, 19 per cent of refrigerators sold in 2005 were in the two new, more efficient classes (A+ and A++). For washing machines, progress was even more rapid: with an increase in sales of 1 per cent in 1996, 38 per cent in 2000 and 90 per cent in 2005. | D2: NOT SDG 7
A3: 10.1787/5k9crzjbpkkc-en | B3: 5cbab6e5118d697ee7147b8b0b34ecf1 | C3: A discussion of the rebound effect in energy efficiency is needed that incorporates not just the expected energy savings from energy efficiency but also the wider socioeconomic outcomes. Policy measures are needed to overcome the market and behavioural failures that lead to less investment in energy efficiency than is optimal. It is important to overcome critical challenges that involve complex synergies and trade-offs among the different aspects of energy efficiency policy. | D3: SDG 7
A4: 10.18356/5b6c49ea-en | B4: cb7bc8e45845a3c9f2ff7666fe2eaddd | C4: While it is correct that, aside from hydro (the potential of which is low but of high quality) and wind (which provides low-quality power), modern renewables continue to be significantly more expensive, economic limits are ultimately a lesser constraint, as they can be overcome with political will and special efForts. In fact, most energy technology debates completely disregard associated socio-political limits. In pluralistic democracies, the “not-in-my-backyard” (NIMBY) attitude is a powerful factor. | D4: SDG 7
A5: 10.1787/5kg51nfc1321-en | B5: baebc2406cec83bb365787cbd8c18104 | C5: This option could lead to achieving the goal of a 40% reduction in energy intensity by 2030. The largest impact in energy intensity reduction will stem from efficiency improvements in the industrial and residential sectors. These products must be rapidly distributed on a large scale to achieve energy savings and reduce worldwide emissions. | D5: SDG 7
A6: 10.1787/5kg20639kgkj-en | B6: 66e3db40126ffb45baee5598c3121304 | C6: The development of a shared evidence base and understanding of the city’s problems will help future planning and enable Sydney to better showcase its strengths and weaknesses to State and Federal policy makers. This is particularly relevant to the sustainability agenda where key stakeholders were beginning to come together across the city. Building on these relationships and partnerships should be a priority, in order act as a catalyst for a citywide sustainability strategy, which could potentially be seen as a working template for future city wide strategic partnerships and work. | D6: NOT SDG 7
A7: 10.18356/fcd1ba6c-en | B7: 1b8b3de79df5c5923493cd5050d3ceae | C7: Indeed, the rising incidence of non-standard employment has widened the gap in earnings distribution and contributed to an increase in poverty. In Germany, the total income gain of households has gone to the richest 10 per cent of households since 2003 (Parma and Vontobel, 2009:129). The recent widening of inequalities marked a complete reversal of the previous trend. | D7: NOT SDG 7
A8: 10.6027/9789289329163-8-en | B8: 2d9020466b5292b7a7e34b4d706eef80 | C8: This kind of system has been used successfully in Norway over a decade. As trees grow they continuously sequester carbon from the atmosphere. As cellulose, hemicellulose, lignin and other wood and bark components will be used for new purposes carbon can be stored for longer times in plastics and fabrics, and for shorter times in pharmaceutical products, chemicals, food and beverages, and so on. | D8: NOT SDG 7
A9: 10.1787/9789264303119-en | B9: f6d5efdef2f9ea14a47527c057a04920 | C9: Compared with other instances of social costs, one may think of tobacco smoking or lead concentration in drinking water, this process has developed reasonably quickly. First, there is public awareness and opinion creation by means of public communication. These may be commercial means of communication, such as television or newspapers, but also non-commercial means of public awareness creation such as demonstrations, sit-ins, public speeches and the like. Again, information is the first step in internalising external costs. This way, the set of choices is transformed into new choices that integrate a higher share of public concerns. | D9: NOT SDG 7
A10: 10.1787/9789264115118-6-en | B10: 8d5c4d3906214299799340e13fe6047d | C10: The project is huge on several scales: at 4 800 MW, the plant will be the seventh-largest in the world, and the estimated construction costs of USD 17.8 billion is equivalent to 10% of South Africa’s GDP. The electricity from the plant will provide much-needed supply to South Africa’s mining and other industries, as well as generally supporting the quality of supply for household users. And being situated close to large low-cost domestic resources of coal provides a secure supply of fuel. The decision by the South African government to support this project was backed up by the World Bank which is providing just over USD 3 billion of loans, and USD 2.5 billion from the African Development Bank (Sovacool and Rafey, 2011). | D10: SDG 7
A11: 10.1787/5k3w6ljtrj0q-en | B11: 6cc45f35957a70dc1f450fbc4ab74b22 | C11: This motivation is still strong with the reality of recession and austerity in many countries making the idea of green employment growth a welcome antidote to the high unemployment rates. Capacity building and skill development within the regional communities are also important benefits of green initiatives. | D11: NOT SDG 7
A12: 10.18356/04b2e7d9-en | B12: 02bac9d17475999b1e8cd569255dca67 | C12: Strategies include building national and regional institutional capacity, cost sharing across borders, governance and regulations, enhancing access to modern energy, developing low-carbon and renewable domestic resources, improving regional energy cooperation and energy security, and promoting private sector participation in energy development. One key focus area is the development of hydropower potential, especially in the Lao People's Democratic Republic. Other activities pertaining to the energy sector include issues related to development of new and renewable sources (including small hydro), addressing the food-energy nexus, standardization and testing. These are captured in the BIMSTEC Memorandum of Understanding on Grid Interconnection. | D12: SDG 7
A13: 10.18356/7e830810-en | B13: 2cd4fdfbe38a99441412e37921a2da5d | C13: Given industry’s substantial contribution to global energy intensity, credible specific industrial energy-efficiency targets must be formulated. But to keep increases in industrial energy consumption to the minimum required to satisfy development needs, future efficiency efforts must be ambitious. They must double today’s pace and reach energy intensity reduction rates similar to those in the 1990s. Doubling the industrial energy-intensity reduction rate is consistent with a similar exhortation made at the global level in the AGECC (2010) report. | D13: SDG 7
... A31: 10.6027/fcafdf5b-en | B31: 52148c3d2fdb1fb63687cf5e2dbe698c | C31: Greenland, the Faroe Islands and Svalbard have experienced an increase in tourism levels as well, though at a lower level than Iceland, with a growth ranging from 15% to 45% since 2012. As the duration of the visits have not increased, the increased spending is caused by a higher daily spending by the tourists. Tourism may create short and long-term profits and jobs for a region leading to economic growth, provided it is managed sustainably. | D31: NOT SDG 7
A32: 10.1787/9789264284319-9-en | B32: 5c18bc73a355e3bb2f41f8006c717c65 | C32: In addition, in 2014, EUR 5.8 mln from local budgets was used to finance eneigy efficiency measures (EEA, 2015). To date, there have been three calls. The first, in 2013, was launched for public institutions (including schools and hospitals), resulting in the selection of 86 projects worth a total of MDL 135 mln (about EUR 78 000 per project on average). | D32: NOT SDG 7 | E32: Could be labelled SDG 7 but there is a spelling mistake in "eneigy"
A33: 10.18356/f00277f1-en | B33: 51623ee78c26efaa4fbc70e63e7d503a | C33: Energy efficiency targets are now in place at all levels of government. Nevertheless, in all countries and economic sectors, increased synergies between renewables and energy efficiency measures are possible, and oftentimes strengthening one will, in turn, strengthen the other. In both technical and policy contexts, renewable energy can have a positive effect on energy efficiency—and vice versa. Each of these steps presents opportunities to strengthen the energy efficiency of the overall system. | D33: SDG 7
A34: 10.6027/9789289330954-4-en | B34: 138cf928dfb2490a23508d1175375c10 | C34: The country's potential in developing energy production technologies like wave power and osmotic power is also substantial. Norway is Europe's largest producer of hydropower, which delivers 99% of the country's electricity. On January 1 2008, Norway had a total installed capacity of 29030 MW at 699 hydropower stations larger than 1 MW. The Kvill-dal hydropower station in Rogaland county is Norway’s largest, with a maximum generating capacity of 1240 MW. | D34: SDG 7
A35: 10.1787/5k3wb8h0dg7h-en | B35: 08f9f7626f2c2baf6922a89d1b569335 | C35: Since 2007 Italy has provided tax relief for energy efficiency improvements to existing buildings including the installation of double-glazed windows, thermal insulation, high-efficiency boilers and the installation of solar panels. In 2009, building owners submitted 240,000 tax credit applications. As the programme was originally expected to be terminated in 2010, the number of applications in 2010 exceeded the previous year by around 71%. | D35: SDG 7
A36: 10.6027/9789289329163-8-en | B36: f8a730809d29ac515eb7c5e34389c1b6 | C36: Consequently, there are more business options for the forest industry and forest-based raw materials than ever before. It still needs to be remembered that all four levels must be able to co-exist also in the future, even if their shares may change. All that can be produced without felling trees, e.g. carbon sinks, berries, game, tourism, etc. | D36: NOT SDG 7
A37: 10.1787/5km5zrrvzr42-en | B37: ab3c26a36fa747b6fc4899fb49a3dab5 | C37: Some energy efficient devices (e.g. variable speed drives) may be more susceptible to voltage or frequency fluctuations on the grid. Energy efficient devices moreover often involve new technology with low operating experience. The highly technical realities underlying such investments result in investors demanding an implicitly higher rate of return to offset the perceived higher risk of energy efficiency projects. Finally, a perception of high transaction costs can emerge because of the small size of EE projects relative to other projects. | D37: SDG 7
