Workbook

Sheet Info
B2: Hello 👋
B4: Welcome to the labeling exercise for SDG 2.
B5: The objective of this exercise is to label 100 texts in terms of their relevance to SDG 2.
B7: Your Labeling Sheet
B8: You have your own personal sheet for assigning the labels. You will find it by clicking on your name in the list at the bottom of this page.
B9: Each sheet has the same 100 texts, but the order in which they appear has been randomized.
B10: Later on, we will put everyone's labels side-by-side. This will help us identify texts with high and low alignment.
B11: At our next meeting, we will discuss the texts where we have disagreements and see if we can reach a consensus for the "true" label for every text.
B12: Please resist the temptation to look at other people's labels until you are done labeling. 🙂
B14: Explanation of Labels
B15: On your personal sheet, you will find the text in column B.
B16: Column C contains a drop-down for picking the appropriate label. The options are:
B18: TRUE | C18: This text is relevant to SDG 2
B19: FALSE | C19: This text is not relevant to SDG 2
B20: SKIP | C20: You can use this if you are not sure about the label
B22: If you want, you can put any comments in column D.
B24: Instructions for Labeling
B25: The text should be annotated as SDG 2 only if:
B27: 1. The text addresses SDG 2 or one of its targets
B28: See the official definitions of SDG 2 and its targets below ("SDG 2 Description & Targets").
B30: AND
B32: 2. The text addresses SDG 2 or its targets directly:
B33: - the text should be directly relevant to SDG 2 or to achieving SDG 2
B34: - if a text only has an indirect or implicit relevance, it should not be labeled SDG 2
B36: AND
B38: 3. The text addresses SDG 2 or its targets specifically:
B39: - the text should be specific to SDG 2 and its targets
... B87: Please click on your name to access your personal labeling sheet. Names are listed in alphabetical order.
B89: Name | C89: Progress (will update automatically)
B90: Finn | C90: =IFERROR(__xludf.DUMMYFUNCTION("SPARKLINE((100-COUNTIF(INDIRECT(B90&""!C:C""), ""TO DO""))/100+0.01,{""charttype"",""bar"";""max"",1.01;""min"",0; ""color1"", ""#4285f4""})"),"") | D90: =(100-COUNTIF(INDIRECT(B90&"!C:C"), "TO DO")) & " / 100" -> 100 / 100
B91: Gib | C91: =IFERROR(__xludf.DUMMYFUNCTION("SPARKLINE((100-COUNTIF(INDIRECT(B91&""!C:C""), ""TO DO""))/100+0.01,{""charttype"",""bar"";""max"",1.01;""min"",0; ""color1"", ""#4285f4""})"),"") | D91: =(100-COUNTIF(INDIRECT(B91&"!C:C"), "TO DO")) & " / 100" -> 52 / 100
B92: Jean-Baptiste | C92: =IFERROR(__xludf.DUMMYFUNCTION("SPARKLINE((100-COUNTIF(INDIRECT(B92&""!C:C""), ""TO DO""))/100+0.01,{""charttype"",""bar"";""max"",1.01;""min"",0; ""color1"", ""#4285f4""})"),"") | D92: =(100-COUNTIF(INDIRECT(B92&"!C:C"), "TO DO")) & " / 100" -> 0 / 100
B93: Meike | C93: =IFERROR(__xludf.DUMMYFUNCTION("SPARKLINE((100-COUNTIF(INDIRECT(B93&""!C:C""), ""TO DO""))/100+0.01,{""charttype"",""bar"";""max"",1.01;""min"",0; ""color1"", ""#4285f4""})"),"") | D93: =(100-COUNTIF(INDIRECT(B93&"!C:C"), "TO DO")) & " / 100" -> 100 / 100
B94: Steve | C94: =IFERROR(__xludf.DUMMYFUNCTION("SPARKLINE((100-COUNTIF(INDIRECT(B94&""!C:C""), ""TO DO""))/100+0.01,{""charttype"",""bar"";""max"",1.01;""min"",0; ""color1"", ""#4285f4""})"),"") | D94: =(100-COUNTIF(INDIRECT(B94&"!C:C"), "TO DO")) & " / 100" -> 100 / 100
B96: Thank you for being part of this exercise and thanks to OSDG for the dataset! ❤️
B98: Text Selection
B99: FYI: You do not need to read this section. We are just documenting how the texts for this exercise were selected.
B101: In total, 100 texts were selected from the OSDG dataset for SDG 2. The reason for selecting each text is documented in the "Source" sheet.
B103: Automatic Selection (50 texts)
B104: 50 texts were selected automatically
...

Sheet Finn
A1: Text ID | B1: Text | C1: SDG 2 Label | D1: Comments (optional)
A2: 2532065ecd054ca65ed9d5102de8d99a | B2: The main change is due to the need to allocate programmes under Inspection Services and Marketing and promotion into new sub-categories. In particular the inspection and control programmes implemented by the inspection agency SENASICA include inspection, pest and diseases and input components. Good budgetary information for the allocation of this expenditure to different sub-categories was not available and allocation was provisionally done in equal amounts. New information is being collected with the view of improving this allocation in the next monitoring cycle. | C2: FALSE
A3: 31b6cccd55e2670d4100d7f334e38649 | B3: The complexity of agricultural ecosystems makes it difficult to accurately measure, quantify and monitor the biogeochemical and natural resource flows that underlie agriculture. There is a lack of analytical tools and mechanisms readily available to measure, value and account for resource use and loss in agricultural production systems. Several efforts are under way to remedy this situation, for example within the framework of the World Overview of Conservation Approaches and Technology (WOCAT) and the Land Degradation Assessment in Drylands (LADA) project. | C3: TRUE | D3: sustainable agriculture (overarching)
A4: bb5b864dcde19e1998e19f292cd99883 | B4: Obesily ond the food system Ironsformolion in Lolin Americo. Climate change and food security: risks and responses. World Economic and Social Survey 2016 -Climate Change Resilience: An Opportunity for Reducing Inequalities. Contribution of Working Groups I, II and III to the Fifth Assessment Report of the Intergovernmental Panel on Climate Change. ( | C4: TRUE
A5: cb38c226212df16bef2e71250c097c15 | B5: Their impacts on nutrition may also vary according to the economic and nutritional context of the country. Agricultural policies that provide appropriate incentives and clear market signals that promote the sustainable intensification and diversification of production will improve nutrition more effectively. On the other hand, the Common Agricultural Policy in European countries actually raises consumer prices of sugar and dairy products relative to prices of fruits and vegetables and thus may have a small positive impact on the overall healthiness of European diets (Capacci eta/., 2012). | C5: TRUE
A6: eb3879fb41704a71e0f27028587a8106 | B6: Promoting niche markets through denomination of origin, eco-labelling, fair trade, organic and slow food initiatives, geographic indication, globally important agricultural heritage systems, and one-village-one-product intiatives may be particularly useful. Therefore, PGRFA include both farmers'varieties/landraces and modern cultivars of staple crops as well as NUS.The development and implementation of policies are a key component in promoting NUS/FSF into agricultural production systems (FAO, 2015a). Following this, the Rome Declaration on Nutrition included the call to "Promote the diversification of crops including underutilized traditional crops, more production of fruits and vegetables, and appropriate production of animal-source products as needed, applying sustainable food production and natural resource management practices" (FAO, 2014a). These commitments have become even more compelling with the imperative of achieving the SDGs by 2030. In general, in developing countries, the attainment of this objective even for staple crops, and more so for NUS, remains a seemingly intractable problem. | C6: TRUE
A7: 8f465586d7975b49d38988535499324d | B7: Credit resources could be re-directed to support long-term investment and increasingly allocated to w'ell-specified innovation, environmental, and infrastructure projects. Consider a gradual downsizing of concessional loans for working capital to commercial producers. Enhance criteria for loan eligibility to better screen out borrowers that would have invested without support. | C7: FALSE
A8: d684a38c613e4fb04288830791241425 | B8: While rice fills the stomach, a rice-dominated diet provides only low to zero amounts of protein, amino acids and essential micronutrients, which can be found, for example, in pulses, fruits, nuts, tubers, vegetables, fish, meat and edible insects. The dependency on rice leads to insufficient intake of nutrient-rich foods, which in turn leads to a significant'nutrition gap'. Dietary diversity is low when there is high consumption of cereals, mainly rice, but relatively low intakes of vegetables, fruits and pulses which are known to be rich in micronutrients and fibre. | C8: TRUE
A9: ed734b54a62ee1b417b8227e3545e68f | B9: This largely reflects investment support for constructing facilities to collect, store and process agricultural products. Environmental cross-compliance requirements are gradually emerging. The six SEE economies are relatively well integrated into the world trading system. All six economies are signatories of the Central European Free Trade Agreement (CEFTA), through which they have achieved full tariff liberalisation on trade in agricultural goods. | C9: TRUE | D9: target 2.b
A10: 1641e7eb2c04fe59dbc2bed76c50e411 | B10: The white sugar premium is projected at nearly USD 100/t, yet narrowing over the decade. Profitability of the ethanol sector should improve slightly in the coming years, because the margin between feedstock and ethanol prices is expected to increase in real terms. With biodiesel demand being mosdy policy and not market driven, biodiesel prices are expected to follow the evolution of vegetable oil prices. After a 2010 cotton price spike, driven by macroeconomic volatility and policy changes in key countries, prices have declined significantly in recent years but cotton prices are expected to remain relatively stable during 2014-23 as the assumptions regarding policy and macroeconomic stability do not indicate any future price run-ups. | C10: TRUE | D10: target 2.c
A11: 4b7d23f7a86b989a624080ef28cde245 | B11: The recent food crisis and slow progress towards the achievement of the Millennium Development Goal of eradicating hunger have highlighted the wide disparities in technologies used and productivity achieved in different agricultural systems. While input and resource-intensive agriculture is the norm in many developed and middle-income developing countries, many developing countries continue to rely on low-input, low-productivity agriculture. Even as the former group of countries need to shift towards less intensive and more environmentally sound methods, farmers in many developing countries would benefit from greater input use. | C11: TRUE
A12: 035b2faad544481608e939c50a4c17a7 | B12: Brazil's cotton production is expected to grow even faster than the world’s largest cotton producer, India, which has a greater potential for higher yield growth as it starts from a low base. During the course of the next ten years, Brazil is expected to draw-down cotton stocks. Changing competition for resources to produce other commodities is also expected to influence the outlook for cotton markets. | C12: FALSE
A13: 27fb4d1c05312bddb8ada4d17838a28e | B13: The regional average dependency ratio (i.e. the ratio of people younger than 15 to the working-age population in the 15-64 year range) totalled 74.7% (UNFPA, 2015). An ever increasing and younger population is a distinctive feature of West Africa: the total population is projected to almost double and approach 600 million by 2050 (OECD/SWAC, 2013). From 1950 to 2010, the percentage of urban dwellers increased from 9% to 41% and this figure is projected to soar to 67% by 2050 (Moriconi-Ebrard, Harre and Heinrigs, 2016, OECD/SWAC, 2013). Urban growth concerns old and new towns, larger cities and smaller and rural centres alike (Ibidem). | C13: FALSE
A14: 9628e25b6601176ef6f0d49f09bc913e | B14: Bt cotton8 and corn, for example, use less herbicides and pesticides, but if these crop varieties develop resistance to the less toxic chemical herbicides and pesticides, future more toxic inputs may be required. In this case, adoption of transgenic crops could have large negative ecological implications if “GE crops are adopted more widely in developing countries where domesticated crops have wild relatives” (Ervin, Glenna and Jussaume, 2010, p. 7). Innovative mechanisms designed to engage the private sector need to be explored: results-based performance contracts—for the development, for example, of improved seed or crop varieties with higher water-stress tolerance and greater responsiveness to fertilizers—granted on a competitive basis may be one means of stimulating private research. | C14: TRUE | D14: sustainable agriculture
A15: f1b3b331d543d8400419570bd9e41e68 | B15: The main conditions for forming a successful PPP include: common objective, mutual benefits, complementarity of human and financial resources, clear institutional arrangements, good governance, transparency and public leadership. The new legal framework for PPPs in agriculture, to be refined in two circulars that MARD is developing, should thus clearly state the respective roles and responsibilities of the public and private sectors. There are a large number of cases, e.g. in providing financial support to agriculture or in food safety regulatory regime, in which co-ordination between various agencies both at the central government level and between central and local governments is weak. | C15: TRUE | D15: target 2.3
A16: 36590da7881cc60021cd712b2fba6988 | B16: Table 10 summarises risk-related policies following this two dimensional approach, which allows one to highlight several general features of New Zealand’s policies. Risk management policies in New Zealand fall predominantly under the efficiency objective. These measures are largely focused on reducing transactions cost (by establishing regulations conducive to competition and adaptation, and creating a stable macroeconomic framework), addressing the problem of asymmetric information (e.g. through research and information), and addressing the problem of externalities (e.g. biosecurity measures). | C16: FALSE
A17: f634804dcae42abe19e97ec75564ac9c | B17: A broader analysis of the financial sector in Myanmar can be found in Chapter 6 on financial sector development. While agriculture employs up to 61.2% of the workforce, only 1-3% of the volume of formal bank loans is extended to the agricultural sector. Although its lending has increased in recent years, it provides only short-term seasonal loans that cover a limited share of the production costs and continues to prioritise rice farmers. Other formal lenders have been unable to fill the gap. | C17: TRUE | D17: target 2.3
A18: 42b7c78961c84bd4b4bf3893c0fdc7e7 | B18: Investment in R&D has resulted in high growth in Brazilian scientific knowledge, particularly within tropical agriculture. Embrapa has provided comprehensive recommendations ranging from how to correct acid soils and low fertility, the development of varieties that are adapted to the low latitudes and higher temperatures of tropical environments, and to pest and disease control and production systems. Universities also produce high level research in areas complementing Embrapa’s activities, such as in nutrition, health and the environment. This mechanism facilitates participation in global or regional agricultural research networks. Embrapa is also actively collaborating on technology transfer and adaptive research with developing economies, with an emphasis on tropical areas in Latin America, the Caribbean and Africa. | C18: TRUE
A19: 29b14c84a982842d81c0feb3200090e8 | B19: As forests are lost, their capacity to sequester carbon is reduced. However, the extent to which the carbon loss due to tropical deforestation is offset by expanding forest areas and accumulating woody biomass in the boreal and temperate zones is disputed. Also relevant are biomass fires, including peatland fires and drained peatlands, which account for emissions of 0.3 and 0.9 GtC02-eq a year respectively). It retains biodiversity and ecosystem functions and, in large land areas, influences local weather patterns, which can have impacts on food production (Siikamaki and Newbold, 2012). Reduction of forest fires improves local air quality which has health benefits for communities living in and around forests Mery et al. | C19: TRUE
A20: cc7c8ddf589e45f25107964d4abcd68d | B20: Excessive use of agrochemicals (pesticides and fertilizers) contaminates waterways. Energy production and climate change are also main causes of water scarcity. For instance, use of traditional sources for energy production results in increased greenhouse gas emissions and climate change, increasing the frequency and intensity of extreme climatic events such as flood and droughts, sea-level rise, and the loss of glacial and polar sea ice, all of which contribute to water scarcity. | C20: TRUE | D20: sustainable agriculture
A21: cf4918c28035c47bd1e98be93c7ca349 | B21: In an integrated world, this difference prevents the regional economy from managing at its own pace the gradual transfer of the active population from agricultural activities to modern-type activities, faced with the import of goods from advanced countries. The sudden appearance on the world market of emerging economies draining the entire investment capacity of the advanced economies may mean that Africa remains limited to exporting primary products (agricultural and mined), postponing industrialisation consistent with the growth of its population. This growth is penalising the consumption and saving potential of households, limiting the ability of the regional market to support a change in production. | C21: FALSE
A22: ca4bdfd976b99a24b155471befc072e8 | B22: Through increasing market size, suitable infrastructure may also promote competition and the adoption of productivity-enhancing technologies. Given such positive externalities, there is often an argument for government provision. Nevertheless, it is also important that framework conditions are designed in a way that encourages private sector infrastructure investment. Without a sufficient network of roads and ports, improvements in farm productivity could result in lower local prices for a commodity at the same time as there is inadequate supply in other provinces. | C22: TRUE | D22: farm productivity (target 2.3)
A23: 1bf623143e7014fc9dd682a2ef7a6c2c | B23: However, line ministries have greater influence in setting NTBs. They are generally more protectionist and influenced by interest groups. Hence trade policy is a continuous battleground, and a change of key ministerial personalities can easily result in a more protectionist trade policy regime. This is the crux of Indonesia’s trade policy challenge: no minister or agency has control over the full array of trade policy instruments, and is able to adopt an economy-wide public interest viewpoint. | C23: FALSE | D23: NTB = non-tariff barriers
A24: 49f3a0536d5bd07600ff64aa74eb63ef | B24: The elimination of most public stocks in OECD countries and the privatization of most State-trading enterprises have concentrated knowledge concerning agricultural commodity availability in the hands of a small number of companies which maintain this information as proprietary. One of the most important elements of the Action Plan on Food Price Volatility, agreed by the G20 Agriculture Ministers at their meeting held in Paris on 22 and 23 June 2011, was the launching of the Agricultural Market Information System (AMIS) to improve market information and transparency of data on current stocks, and promote coordination of policy responses (see Ministerial declaration, para. Second, assuming the role traditionally played by the United States of America and China as stock holders, the international community should maintain a minimum level of world food stock. | C24: TRUE
A25: f66a2809d8a51e9b7507fe2de3e11b9b | B25: The basic model also assumes competition in the market for the commodity and the absence of any other market distortions. A general result is that the main effect of a market distortion in this context is to change the distribution of research benefits, with comparatively small effects on the total benefits. Similar results apply to the other types of extensions to the basic model that may be introduced to allow for multiple markets or proprietary technology. | C25: FALSE
A26: e20deb68aff05f36aba8681675b31a51 | B26: In the model ECIRS payments are then triggered and the representative mixed crop and livestock farm receives the equivalent to the average receipt of ECIRS in 2007-08 (AUD 37 000)l0. On the other hand, the model assumes that ECRP also triggered under the same circumstance, but it is paid to the farmer only if the realized income is below the level set by income test criteria (AUD 62 per fortnight). The level of the ECRP is chosen at the average receipt of ECRP per recipient in 2007-08 (AUD 13 045). | C26: TRUE | D26: - ECIRS provides interest rate subsidies to farm enterprises and small businesses that are viable in the long term but are in financial difficulties
A27: 43be08e156654740fbb5d93f102cd3d9 | B27: A Commodity Levy Act (1990) empowers producers to self-impose levies through a vote in order to finance the “industry good” activities. Once voted, the levy becomes obligatory for all commercial producers of a commodity and is charged on each unit marketed as a type of sales tax. Levies are collected by downstream operators and transferred to industry good bodies.17 The obligatory character of the levy is grounded by the necessity to avoid a “free-rider problem”. However, this compulsory levy is introduced through voting and therefore is self-imposed. | C27: FALSE
A28: f8c5ee200647dd1aa73041663e5373eb | B28: Fertiliser subsidies remain by far the most important programme through which the government provides budgetary support to agriculture. This subsidy is received indirectly by farmers as is channelled through fertiliser companies. These companies are responsible for lowering the price of their final product, which in turn benefits farmers (OECD, 2013b). To ensure the success of the programme, beneficiaries also receive technical guidance from a local agriculture extension officer. The giant is based on a proposal prepared by groups of farmers. The Indonesian government, through the Raskin Programme, buys a given percentage of the total output of rice produced by small-scale farmers. | C28: TRUE | D28: target 2.b
A29: 61b42b465822d1bd5543015dcc685da0 | B29: Fresh water resources may be adequate in particular regions, but a number of regulatory and infrastructure impediments often obstruct their use for productive purposes. For example, fresh water resources, including local groundwater or surface water are often transboundary, so that their management is seriously hampered by the lack of coordinated regional strategies (Nin-Pratt et al., In developing countries, markets for agricultural inputs and outputs, finance and other services, are often poorly developed, with small volumes traded, prone to large seasonal variability in demand and supply and significant difficulties in enforcing interpersonal contracts (Poulton et al., | C29: TRUE | D29: target 2.c
A30: 84f032619a01d1494cb406973276d986 | B30: To feed an additional two billion people by 2050, food production will need to increase by half globally (FAO, SOFI, 2017). Increasing the production of traditional staple crops is unlikely to meet the increasing demand, in major irrigated wheat, rice and maize systems, yields appear to be near 80 percent of the yield potential. The second challenge is the nutrition gap between what foods are grown and available, and what foods are needed for good health. This requires increasing the availability and access to the nutritious foods necessary for a healthy diet. | C30: TRUE
A31: a6a2b36395affc1ae47335bc6fff0084 | B31: Second, demand elasticities are relatively small with respect to price and supply elasticities are also low, at least in the short run. In order to get supply and demand back into balance after a supply shock, prices therefore have to vary rather strongly, especially if stocks are low. Third, because production takes considerable time in agriculture, supply cannot respond much to price changes in the short term, though it can do so much more once the production cycle is completed. The resulting lagged supply response to price changes can cause cyclical adjustments that add an extra degree of variability to the markets concerned. | C31: FALSE
A32: 81fea12d7e25606f984f70ecd9b6c967 | B32: North Cameroon had an estimated 9 306 km of roads in 2010,8% of them paved, and a density of 0.057 km/km2. Unpaved roads link areas of production to urban consumption centres. The dynamics of market creation have determined a spatial configuration that depends on the quality of the road network, unpaved vs. paved roads. | C32: FALSE
A33: fef3a280389f177360d6860a671d3a06 | B33: Particular attention is often paid to sustainable, or efficient, water use. Because the agriculture sector demands significant amounts of fresh water, a number of policies in both developing and developed countries target the efficient use of irrigation water. A strong call to recognise the importance of improving the efficiency of water and soil use in a sustainable manner by the agricultural sector was made by G20 leaders and G20 Agricultural Vice Ministers in May and June 2012. | C33: TRUE
A34: 57a447c3985789b8ee08e321728246c7 | B34: The federal government complements these programmes through support to biophysical research and other activities. Most farm-level environmental programmes are designed and administered by provincial governments. Major support policies continue to be delivered under the heading of business risk management. Those measures provide support in case of income declines, co-finance savings, support production insurance and provide assistance in case of natural disasters. | C34: TRUE
A35: f54d905902a6f8d57ce12177d1fb2856 | B35: In 2014, 85% of procurement funds were used in this manner (CONAB-PAA, 2014). A significant share of PAA procured supplies (34% in 2014) is used for the school meal programme. In 2009 the National School Meal Program (PNAE) required public schools to allocate at least 30% of food expenditures to direct purchases from family farmers. Since 2011 under the Brazil without Extreme Poverty Plan, PAA procurement is specifically targeted to the 16 million persons living in extreme poverty with monthly income below BRL 70. In 2014, nearly 24 000 PAA suppliers, or 47%, fell within this category. The National Program for Biodiesel Production and Use (PNPB), which contains special provisions for family farmers, was launched by the Brazilian Government in 2005. | C35: TRUE | D35: target 2.3
A36: a50199e9d1481614a8ec3f1a6cc6e024 | B36: For the projection period, biofuel markets are projected to be highly influenced by mandates and other incentives in countries all over the world, with the US, Brazil and the EU playing major roles, respectively, on ethanol and biodiesel markets. Based on sustained political support for biofuels, the Outlook projects increasing world biofuel prices and these will also be underpinned by rising crude oil and energy prices. The world ethanol price2 should follow an increasing trend to reach USD 54.4 per hi in 2019 supported by demand conditions in the US market where the Conventional Renewable Fuels mandate is assumed to be binding over the entire projection period. These quantities are far above the average 2007-09 base levels. | C36: FALSE
A37: deffd5c9a8491d5003383c054b191157 | B37: Creating such an environment is complementary to the provision of more traditional public goods such as improved infrastructure, animal and plant health, education and information systems, and extension. Improvements in these areas could bring substantial long-term gains to agricultural producers through more transparent markets, improved price formation, and, ultimately, higher agricultural incomes. Benefits would also accrue to other agents of the supply chain, including food consumers for whom more competitive food chains would provide higher quality products. Because these characteristics vary with the product, and the location or size of the farm, the focus is on specific subsectors: wheat, dairy and beef, the three largest sub-sectors of Kazakhstan’s agro-food system. | C37: TRUE
A38: 3767ad4e0cbd8df42c933d4249bd30d4 | B38: This is where measures such as compensation and adjustment assistance come into play. This is sometimes interpreted (if not criticised) as an ideological position representing the entrenched philosophy of economic liberalism (or neoliberalism). Yet, there are veiy good practical reasons behind that principle. Three thoughts are particularly relevant. | C38: FALSE
A39: 2186a2325cf67acf84393267d9a262cc | B39: Allowing for the spillover benefits into other states, state-specific agricultural research investments generated national benefits of between USD 10 and USD 70 per research dollar, averaging USD 32 across the states. The marginal benefit-cost ratio for USDA intramural research was comparable, at USD 18 per dollar invested in research. In fact, however, these ratios are consistent with internal rates of return at the smaller end of the range compared with the general results in the literature as reviewed by Alston et al. ( Some internal rates of return are reported here to facilitate comparisons with other studies. | C39: TRUE | D39: target 2.a
A40: f0fcfbe4aeb7463ebf8563148793d827 | B40: This might be particularly true in Indonesia where large fertiliser subsidies are channelled through fertiliser suppliers and not provided to farmers directly. In light of expressed government objectives, these proposals highlight policy options that are potentially more effective and efficient than some existing policy measures. Food security would be greatly enhanced by making agriculture a more attractive sector for investors. | C40: TRUE
...

Sheet Gib
A1: Text ID | B1: Text | C1: SDG 2 Label | D1: Comments (optional)
A2: 951e6ab5b89e7d7608cd0e328990577d | B2: However, the CAP 2014-20 offers more flexibility to member states to re-introduce commodity-specific and output-linked measures. A better alternative would be for member states to focus support on measures to improve the long-term productivity, profitability, sustainability and competitiveness of the sector. The "Plan to Create Vitality for Agricultural, Forestry and Fishery Industries and Local Communities” aims at revitalising the agricultural sector in view of significant drops in output and farming incomes over the past two decades. | C2: TRUE
A3: f1b3b331d543d8400419570bd9e41e68 | B3: The main conditions for forming a successful PPP include: common objective, mutual benefits, complementarity of human and financial resources, clear institutional arrangements, good governance, transparency and public leadership. The new legal framework for PPPs in agriculture, to be refined in two circulars that MARD is developing, should thus clearly state the respective roles and responsibilities of the public and private sectors. There are a large number of cases, e.g. in providing financial support to agriculture or in food safety regulatory regime, in which co-ordination between various agencies both at the central government level and between central and local governments is weak. | C3: TRUE
A4: 1e1ff85737474f25d41d65e9303eda49 | B4: Agreements to do so can be reached at the bilateral, regional or multilateral levels. The pursuit of food self-sufficiency to mitigate international risks is a costly policy that undermines the function of the international trading system, making markets thinner, more volatile and therefore riskier than if countries were to adopt open trade policies. In the face of both international and domestic risks, such as that of a failed harvest, a country which uses trade barriers to promote self-sufficiency because of the fear of trade interruptions may find itself exposed to greater potential losses than if it had remained open to international trade. At the national level, some developing countries may be vulnerable to imported instability, notably if their consumption is centred around just one or two food staples, and if their imports are sourced from just one or two countries. These risks can be mitigated by promoting more diversified diets (something that happens naturally to a degree as incomes rise) and by diversifying trading partners. | C4: TRUE
A5: 42b7c78961c84bd4b4bf3893c0fdc7e7 | B5: Investment in R&D has resulted in high growth in Brazilian scientific knowledge, particularly within tropical agriculture. Embrapa has provided comprehensive recommendations ranging from how to correct acid soils and low fertility, the development of varieties that are adapted to the low latitudes and higher temperatures of tropical environments, and to pest and disease control and production systems. Universities also produce high level research in areas complementing Embrapa’s activities, such as in nutrition, health and the environment. This mechanism facilitates participation in global or regional agricultural research networks. Embrapa is also actively collaborating on technology transfer and adaptive research with developing economies, with an emphasis on tropical areas in Latin America, the Caribbean and Africa. | C5: TRUE
A6: 43be08e156654740fbb5d93f102cd3d9 | B6: A Commodity Levy Act (1990) empowers producers to self-impose levies through a vote in order to finance the “industry good” activities. Once voted, the levy becomes obligatory for all commercial producers of a commodity and is charged on each unit marketed as a type of sales tax. Levies are collected by downstream operators and transferred to industry good bodies.17 The obligatory character of the levy is grounded by the necessity to avoid a “free-rider problem”. However, this compulsory levy is introduced through voting and therefore is self-imposed. | C6: FALSE
A7: 3767ad4e0cbd8df42c933d4249bd30d4 | B7: This is where measures such as compensation and adjustment assistance come into play. This is sometimes interpreted (if not criticised) as an ideological position representing the entrenched philosophy of economic liberalism (or neoliberalism). Yet, there are veiy good practical reasons behind that principle. Three thoughts are particularly relevant. | C7: FALSE
A8: e72f5ec6d9c77829b70282d2aec81af8 | B8: This could imply that there is either limited awareness among the potential beneficiaries about this option or that this scheme provides few additional incentives to farmers as compared to the standard Income Equalisation Regime. It would be useful to explore the reasons for the lack of uptake of the New Start-up Grants, which could be related to overly strict criteria for access by potential beneficiaries or to the levels of the grants. As noted, this facility provides partial compensation for the restoration of “non-insurable” infrastructure, pasture and plantings. The rationale for this support is that insurance for such damage is not available to farmers on the commercial insurance market. | C8: TRUE
A9: f54d905902a6f8d57ce12177d1fb2856 | B9: In 2014, 85% of procurement funds were used in this manner (CONAB-PAA, 2014). A significant share of PAA procured supplies (34% in 2014) is used for the school meal programme. In 2009 the National School Meal Program (PNAE) required public schools to allocate at least 30% of food expenditures to direct purchases from family farmers. Since 2011 under the Brazil without Extreme Poverty Plan, PAA procurement is specifically targeted to the 16 million persons living in extreme poverty with monthly income below BRL 70. In 2014, nearly 24 000 PAA suppliers, or 47%, fell within this category. The National Program for Biodiesel Production and Use (PNPB), which contains special provisions for family farmers, was launched by the Brazilian Government in 2005. | C9: TRUE
A10: 27fb4d1c05312bddb8ada4d17838a28e | B10: The regional average dependency ratio (i.e. the ratio of people younger than 15 to the working-age population in the 15-64 year range) totalled 74.7% (UNFPA, 2015). An ever increasing and younger population is a distinctive feature of West Africa: the total population is projected to almost double and approach 600 million by 2050 (OECD/SWAC, 2013). From 1950 to 2010, the percentage of urban dwellers increased from 9% to 41% and this figure is projected to soar to 67% by 2050 (Moriconi-Ebrard, Harre and Heinrigs, 2016, OECD/SWAC, 2013). Urban growth concerns old and new towns, larger cities and smaller and rural centres alike (Ibidem). | C10: FALSE
A11: cf4918c28035c47bd1e98be93c7ca349 | B11: In an integrated world, this difference prevents the regional economy from managing at its own pace the gradual transfer of the active population from agricultural activities to modern-type activities, faced with the import of goods from advanced countries. The sudden appearance on the world market of emerging economies draining the entire investment capacity of the advanced economies may mean that Africa remains limited to exporting primary products (agricultural and mined), postponing industrialisation consistent with the growth of its population. This growth is penalising the consumption and saving potential of households, limiting the ability of the regional market to support a change in production. | C11: FALSE
A12: 29b14c84a982842d81c0feb3200090e8 | B12: As forests are lost, their capacity to sequester carbon is reduced. However, the extent to which the carbon loss due to tropical deforestation is offset by expanding forest areas and accumulating woody biomass in the boreal and temperate zones is disputed. Also relevant are biomass fires, including peatland fires and drained peatlands, which account for emissions of 0.3 and 0.9 GtC02-eq a year respectively). It retains biodiversity and ecosystem functions and, in large land areas, influences local weather patterns, which can have impacts on food production (Siikamaki and Newbold, 2012). Reduction of forest fires improves local air quality which has health benefits for communities living in and around forests Mery et al. | C12: FALSE | D12: Could be SDG 2.4 The clause "which can have impacts on food production" makes it vaguely relevant to SDG 2, but it is more like fact-stating to support argument on negative impacts of deforestation and forest fires.
A13: 316b127338438827457845f021ab60d8 | B13: Relying on a very small fraction of staple crops for our diet has dire implications for both food security and nutrition. The lack of genetic diversity within the gene pools of the dominant cultivated crops, leavesagricultural systems vulnerable to pests, diseases and other abiotic stresses. Agricultural sustainability relies on a healthy interaction between agriculture and nature. | C13: TRUE
A14: 3b995cc3ee1388e59def7315594577cc | B14: Since then IAARD, has taken steps, through ICATAD, to develop a research consortium programme with universities, establish partnership programmes with private companies such as PT DuPont Indonesia, and increase collaboration with local governments. Finally, although the AIATs are crucial to strengthen the linkages between research at the central level and extension agents in the districts, it is debatable whether each province needs such an agency. A system by which AIAT centres are positioned with agro-ecological zone specialisations, serving all provinces concerned, would foster cross-province co-operation, lead to less fragmentation and reduce the potential for duplication of efforts and functions at the provincial level (World Bank, 2012). Research in each province should be focused on two or three commodities having highest comparative advantages or potential. | C14: TRUE
A15: 61b42b465822d1bd5543015dcc685da0 | B15: Fresh water resources may be adequate in particular regions, but a number of regulatory and infrastructure impediments often obstruct their use for productive purposes. For example, fresh water resources, including local groundwater or surface water are often transboundary, so that their management is seriously hampered by the lack of coordinated regional strategies (Nin-Pratt et al., In developing countries, markets for agricultural inputs and outputs, finance and other services, are often poorly developed, with small volumes traded, prone to large seasonal variability in demand and supply and significant difficulties in enforcing interpersonal contracts (Poulton et al., | C15: FALSE
A16: e55b1921e81e682737e0ff171ece0eb6 | B16: If land owners are not willing to transfer the land and leave it, the investor does not have the right to lease the land and cany out its investment.” It should be noted that although the government discourages slash and bum cultivation, i.e. shifting cultivation, such a system can be sustainable and deliver environmental goods in areas where demographic pressure is relatively low. An approach tailored to the characteristics of each geographical area should thus be taken. | C16: TRUE
A17: fe5d56c0dd78ec96e422af746a3fb392 | B17: This trend is expected to continue as a result of growth in incomes. A number of studies have looked at the environmental consequences of consumption of animal-source food, usually focusing on GHG emissions and land use (INRA and CIRAD, 2009, Erb et al., Using life cycle assessments, they generally conclude that alternative diet scenarios with less animal-source food could contribute to reducing global GHG emissions, and have positive impacts on human health. Healthy diets also feature dairy products in moderation, unsalted seeds and nuts, small quantities of fish and aquatic products, and very limited intake of processed foods that are high in fat, sugar or salt and low in micronutrients (FAO and FCRN, 2016). | C17: FALSE
A18: 36590da7881cc60021cd712b2fba6988 | B18: Table 10 summarises risk-related policies following this two dimensional approach, which allows one to highlight several general features of New Zealand’s policies. Risk management policies in New Zealand fall predominantly under the efficiency objective. These measures are largely focused on reducing transactions cost (by establishing regulations conducive to competition and adaptation, and creating a stable macroeconomic framework), addressing the problem of asymmetric information (e.g. through research and information), and addressing the problem of externalities (e.g. biosecurity measures). | C18: FALSE
A19: 1bf623143e7014fc9dd682a2ef7a6c2c | B19: However, line ministries have greater influence in setting NTBs. They are generally more protectionist and influenced by interest groups. Hence trade policy is a continuous battleground, and a change of key ministerial personalities can easily result in a more protectionist trade policy regime. This is the crux of Indonesia’s trade policy challenge: no minister or agency has control over the full array of trade policy instruments, and is able to adopt an economy-wide public interest viewpoint. | C19: FALSE
A20: 4f0fd447ddc38d58bc9844fb18d549a8 | B20: The trouble is, however, that many cities are simply unable to absorb current rates of natural population growth, let alone more rural emigration. Thus, although a great deal of focus is placed on reducing the ills of rapid urbanisation -including overburdened social services, expanding slums, pollution, crime, poverty and hunger - a greater emphasis is also needed on rural areas to stem the tide of rural-urban migration. This means developing many more employment opportunities, including in new' non-agricultural industries, w'ith an emphasis on jobs attractive to the rural youth -those most likely to leave and most needed to rejuvenate rural areas economically and demographically (OECD, 2006). | C20: FALSE
A21: 31f16babe517b5d3e4eb4cf6364b9df7 | B21: In many developing countries, a significant number of poor families face poverty, hunger, food insecurity and malnutrition, which intensify with adverse biophysical growing conditions and poor socio-economic infrastructure (Wani, etal., Crop production, which is vital to global food security, is already being affected by climate change, more so in impoverished communities. It has been predicted that over the next decades, billions of people, especially those living in developing countries, will face water and food shortages, and greater risks to health and life because of climate change. | C21: TRUE
A22: 4853cc7249bda7f9bce65366b53f0c92 | B22: These problems would be best addressed by investing in infrastructure and agricultural research and development. The scale of costs of buffer stocks thus leads to major opportunity costs because not enough investments are made in those programmes that are best suited to tackle volatility. World Bank (2012b) notes that as a result, buffer stocks in Kenya, Malawi and Zambia are even thought to increase price volatility because they were not able to address the causes of volatility and took away resources from programmes that could. | C22: TRUE
A23: a6a2b36395affc1ae47335bc6fff0084 | B23: Second, demand elasticities are relatively small with respect to price and supply elasticities are also low, at least in the short run. In order to get supply and demand back into balance after a supply shock, prices therefore have to vary rather strongly, especially if stocks are low. Third, because production takes considerable time in agriculture, supply cannot respond much to price changes in the short term, though it can do so much more once the production cycle is completed. The resulting lagged supply response to price changes can cause cyclical adjustments that add an extra degree of variability to the markets concerned. | C23: FALSE
A24: fef3a280389f177360d6860a671d3a06 | B24: Particular attention is often paid to sustainable, or efficient, water use. Because the agriculture sector demands significant amounts of fresh water, a number of policies in both developing and developed countries target the efficient use of irrigation water. A strong call to recognise the importance of improving the efficiency of water and soil use in a sustainable manner by the agricultural sector was made by G20 leaders and G20 Agricultural Vice Ministers in May and June 2012. | C24: TRUE
... A30: 41d828d857412f56a5bf4928d7a8f126 | B30: The delegation used sport as a tool to unite and engage with the community. In partnership with the One World Play Project and Chevrolet, it donated over 11,000 footballs and hosted a friendly youth football match and other organized sporting activities. During the trip, the delegation met with representatives of the United States Agency for International Development (USAID), and with the Malawian Ministries of Lands, Housing and Urban Development, Health, Youth and Sports Development, and Agriculture, Irrigation and Water. | C30: FALSE
A31: 4e5237c26875eab28d98e0ca6fc96f61 | B31: Such scenarios may constitute “extreme events”, with a low probability but severe consequences if the event happens. A more likely scenario is that a particular trading partner may block or impede trade temporarily, with implications for the prices that an importing country is obliged to pay. For example, India cut off rice exports to Bangladesh in 2007 in order to lower prices on its domestic market (Dorosh and Rashid, 2012). | C31: TRUE | D31: Could be false. The passage gives an example of an event that was against 2b.
A32: 0b0a4b7011c0f63bc9fe3bd6504045d7 | B32: She would also like to thank the guest bloggers and other contributors to the SWAC @ Expo Milano website who engaged in discussions on the state and prospect of women's empowerment and gender equality in West Africa over several months, sharing their ideas and experiences and raising challenging questions. She has conducted research, co-ordinated policy analysis and published on gender, migration, conflict, peace and security, land reform and regional integration issues. She has also designed and co-ordinated the implementation of human resources and organisational development-related projects and processes in the areas of: job evaluation, organisational design, diversity and change management. Previous roles include: UNV Programme Officer at the UNDP Senegal Office, Policy Analyst at the Sahel and West Africa Club Secretariat of the OECD, and Human Resources Manager and OD Consultant at the International Institute for Environment and Development (IIED). | C32: FALSE
A33: 49f3a0536d5bd07600ff64aa74eb63ef | B33: The elimination of most public stocks in OECD countries and the privatization of most State-trading enterprises have concentrated knowledge concerning agricultural commodity availability in the hands of a small number of companies which maintain this information as proprietary. One of the most important elements of the Action Plan on Food Price Volatility, agreed by the G20 Agriculture Ministers at their meeting held in Paris on 22 and 23 June 2011, was the launching of the Agricultural Market Information System (AMIS) to improve market information and transparency of data on current stocks, and promote coordination of policy responses (see Ministerial declaration, para. Second, assuming the role traditionally played by the United States of America and China as stock holders, the international community should maintain a minimum level of world food stock. | C33: TRUE
A34: 1a0f836c1335da69e8531cd2cad1e33b | B34: A gendered approach to environmental assessment also examines the ways environments and environmental relationships shape, create and sustain gender norms. What are the social costs and consequences of differential gendered environmental relationships? And what is the dynamic relationship between environmental conditions and changes and gender inequality? | C34: FALSE
A35: e1ac8d518cefb597bc5681da901074c1 | B35: This was done through external consultancies by universities (Sao Paulo and Campinas, for example) and private companies such as Macroplan, from Rio de Janeiro. In addition, Embrapa has been training its staff on strategic planning methodologies, in some cases together with state R&D organisations. This strategic planning system is nationally coordinated at Embrapa by a central unit named Strategic Management Secretariat. | C35: TRUE | D35: "Embrapa" makes it highly related to SDG 2. Without the term, the passage will not sound relevant.
A36: 6379115dde7df3fd24608d79ab0e9a29 | B36: These figures most likely underestimate the contribution of off-farm earnings because they capture only the income coming from activities integrated from the accounting standpoint either fully or partly within the farm business. However, studies on rural diversification indicate that the majority of alternative enterprises of agricultural households are financially and structurally independent of the farm business (OECD, 2009e). For example, around 20% of living expenses of those households involved in dairying and sheep and beef farming originate from off-farm income (MAF, 2009e). | C36: TRUE | D36: Could be False. The passage calls for considering off-farm income when estimating farmers' income, probably for SDG 2.3
A37: a50199e9d1481614a8ec3f1a6cc6e024 | B37: For the projection period, biofuel markets are projected to be highly influenced by mandates and other incentives in countries all over the world, with the US, Brazil and the EU playing major roles, respectively, on ethanol and biodiesel markets. Based on sustained political support for biofuels, the Outlook projects increasing world biofuel prices and these will also be underpinned by rising crude oil and energy prices. The world ethanol price2 should follow an increasing trend to reach USD 54.4 per hi in 2019 supported by demand conditions in the US market where the Conventional Renewable Fuels mandate is assumed to be binding over the entire projection period. These quantities are far above the average 2007-09 base levels. | C37: FALSE | D37: Could be True. This is not directly related to food, but more on agricultural production: ethanol.
A38: 2662c39786dae46250a758b1ba81ca25 | B38: Increasing export shares in almost all commodity markets is being achieved by a combination of strategies. Not only are they displacing traditional exporters and competitors with lower cost products or by growing faster, they are also becoming dominant in regional markets which can provide a springboard for further international market expansion. From Figure 1.10, non-OECD countries are projected to show the strongest percentage increase in exports by 2019, relative to the 2007-09 base, for oilseeds (59%), poultry (54%), wheat (50%), skim milk powder (43%), and cheese and vegetable oils (39%). On the other hand, OECD countries as a whole will tend to lose export shares in many commodities to non-OECD countries over the Outlook period. For the OECD area the largest gain in exports by 2019 compared to 2007-09, are for protein meals (49%), vegetable oils (38%) and rice (16%). Trade shares continue to be dominated in absolute terms by the OECD countries and their long established industries for a range of products (with projected global market share in 2019 shown in brackets) such as for: wheat (54%), coarse grains (60%), pig meat (80%), butter (79%), cheese (65%), whole milk powder (66%) and skim milk powder (73%). | C38: TRUE | D38: Status about trade gain-loss in agricultural products
A39: eefdfe05370819034d448c939faa2107 | B39: The impact of environmental and climate constraints on global food supply. In: Economic Analysis of Land Use in Global Climate Change Policy, edited by T. Hertel, S. Rose and R. Tol, Routledge, USA. Land Use Policy, 24,562-575. Assessment of Fertiliser Use by Crop at the Global Level 2006/07-2007/08. | C39: FALSE | D39: Just paper title. The content is likely to be highly relevant
A40: f634804dcae42abe19e97ec75564ac9c | B40: A broader analysis of the financial sector in Myanmar can be found in Chapter 6 on financial sector development. While agriculture employs up to 61.2% of the workforce, only 1-3% of the volume of formal bank loans is extended to the agricultural sector. Although its lending has increased in recent years, it provides only short-term seasonal loans that cover a limited share of the production costs and continues to prioritise rice farmers. Other formal lenders have been unable to fill the gap. | C40: TRUE
A41: cb38c226212df16bef2e71250c097c15 | B41: Their impacts on nutrition may also vary according to the economic and nutritional context of the country. Agricultural policies that provide appropriate incentives and clear market signals that promote the sustainable intensification and diversification of production will improve nutrition more effectively. On the other hand, the Common Agricultural Policy in European countries actually raises consumer prices of sugar and dairy products relative to prices of fruits and vegetables and thus may have a small positive impact on the overall healthiness of European diets (Capacci eta/., 2012). | C41: TRUE
A42: 8f465586d7975b49d38988535499324d | B42: Credit resources could be re-directed to support long-term investment and increasingly allocated to w'ell-specified innovation, environmental, and infrastructure projects. Consider a gradual downsizing of concessional loans for working capital to commercial producers. Enhance criteria for loan eligibility to better screen out borrowers that would have invested without support. | C42: FALSE
A43: a7c3ee7de4571070751b03e661403dbc | B43: Special thanks go to Thomas Chalaux and Clara Garcia for statistical support and Nadine Dufour and Mercedes Burgos for editorial assistance. The scale of the ongoing transition is highlighted by government plans to grant urban residential status to 100 million rural migrants by 2020. This structural adjustment process can deliver substantial opportunities for the rural economy and China as a whole, but entails major challenges calling for continued reform efforts. | C43: FALSE
A44: bf8482b7a0cdb611a351547eb4c40774 | B44: In 2011, a federal programme PRONATEC was launched and now covers 8 million students. Since 2013, it includes a component targeted to rural youngsters: PRONATEC Countryside. For example, in university education, the number of agricultural courses for bachelor degrees reached 830 in 2011, a six-fold increase over 1991, which covers only full-time studies, and does not include distance courses or MBAs (Table 5.1). | C44: FALSE
A45: 7375674a23df762040d9e4eed874a203 | B45: This ‘bird’s eye view’ of the issues provides insights that would otherwise remain hidden, useful in addressing hunger and environmental degradation in an integrated way. The overlaying of visual data representations provides a picture of the interrelation of land, people, and prosperity, and also reveals areas of causal overlap, highlighting key hotspots and areas with synergistic potential—opportunities for win-win scenarios. This method, applied elsewhere, would allow the targeting of funds to key areas, improving efficiency of resources used. | C45: FALSE | D45: addressing hunger-environmental degradation is an example use-case of suggested method. This is too vague to be about SDG 2.
...

Sheet Jean-Baptiste
A1: Text ID | B1: Text | C1: SDG 2 Label | D1: Comments (optional)
A2: 29b14c84a982842d81c0feb3200090e8 | B2: As forests are lost, their capacity to sequester carbon is reduced. However, the extent to which the carbon loss due to tropical deforestation is offset by expanding forest areas and accumulating woody biomass in the boreal and temperate zones is disputed. Also relevant are biomass fires, including peatland fires and drained peatlands, which account for emissions of 0.3 and 0.9 GtC02-eq a year respectively). It retains biodiversity and ecosystem functions and, in large land areas, influences local weather patterns, which can have impacts on food production (Siikamaki and Newbold, 2012). Reduction of forest fires improves local air quality which has health benefits for communities living in and around forests Mery et al. | C2: TO DO
A3: a50199e9d1481614a8ec3f1a6cc6e024 | B3: For the projection period, biofuel markets are projected to be highly influenced by mandates and other incentives in countries all over the world, with the US, Brazil and the EU playing major roles, respectively, on ethanol and biodiesel markets. Based on sustained political support for biofuels, the Outlook projects increasing world biofuel prices and these will also be underpinned by rising crude oil and energy prices. The world ethanol price2 should follow an increasing trend to reach USD 54.4 per hi in 2019 supported by demand conditions in the US market where the Conventional Renewable Fuels mandate is assumed to be binding over the entire projection period. These quantities are far above the average 2007-09 base levels. | C3: TO DO
